Workbook

Sheet Leia-me
A1: MOSAICO · A Manhã do Carro-Forte · O Impostor — Matriz do caso
A3: O que é | B3: A "bíblia antes do código" (Guia técnico, seção 18): tudo o que o jogo precisa saber da história, em tabelas. Fonte única: A_Manha_do_Carro_Forte_-_O_impostor_revisao2.docx (revisão 2, 4/10/2026). Nada aqui é texto para o jogador.
A4: Partidas lógicas | B4: Três: S (impostor: Subgerente, versão de referência), G (Gerente) e V (Caixa Veterano). O ato é o mesmo; mudam só os pontos A1–A10.
A5: Casas | B5: Núcleo 6 → +1º bloco = 8 → +2º = 10 → +3º = 12 → +Transportador = 13 personagens jogáveis. O oculto (Monitor Remoto), o vigia de fora (Operador de Rádio) e os três de apoio (Motorista, Segurança Interno, Caixa Novato) estão em toda casa, sempre do sistema.
A6: Abas de estrutura | B6: Partidas · Ajustes A1–A10 · Elenco · Casas · Linha do tempo · Janela 87 s · Postos na janela · Perspectivas · Lugares · Rotas e visão · Acessos · Capítulos · Seis eixos · Provas e cobertura · Perguntas · Plantações · RA
A7: Abas de falas | B7: Prólogo e Cap 1 a Cap 8: cada fala do texto público (diretas e indiretas), com quem fala, canal, função, prova, ponto de ajuste, variação G/V e se sai quando o personagem não está na casa. As 6 colunas de personalidade estão vazias: é a próxima passada.
A8: Variantes Cap 8 | B8: Confissão, saída (A10), mudanças na acusação e no epílogo de cada partida.
A9: Pendências | B9: Contradições e buracos encontrados ao montar a matriz, com proposta e a decisão do Mario. Verde = decidido ou aplicado no jogo.
A10: Mudanças no docx | B10: Lista do que mudar no docx da revisão 2 para a revisão 3: texto atual, texto novo e motivo. O docx não foi alterado.
A11: Cores | B11: Amarelo = linha com ponto de ajuste (muda por partida). Laranja = falta fonte / pendência. Verde = coberto.
A12: Ids | B12: Personagens pela função, minúsculas, sem acento (gerente, caixa_veterano…). Lugares com hífen (sala-gerencia, arquivo-morto…). Falas: cN-NNN.
A13: Rascunho | B13: As perguntas por capítulo são proposta minha a partir das fichas dos capítulos; precisam da sua aprovação.

Sheet Resumo
A1: Aba | B1: Linhas | C1: Com ajuste | D1: Saem se ausente
A2: Prólogo | B2: =COUNTA('Prólogo'!A2:A15) | C2: =COUNTIF('Prólogo'!J2:J15,"A*") | D2: =COUNTIF('Prólogo'!M2:M15,"sim")
A3: Cap 1 | B3: =COUNTA('Cap 1'!A2:A45) | C3: =COUNTIF('Cap 1'!J2:J45,"A*") | D3: =COUNTIF('Cap 1'!M2:M45,"sim")
A4: Cap 2 | B4: =COUNTA('Cap 2'!A2:A47) | C4: =COUNTIF('Cap 2'!J2:J47,"A*") | D4: =COUNTIF('Cap 2'!M2:M47,"sim")
A5: Cap 3 | B5: =COUNTA('Cap 3'!A2:A35) | C5: =COUNTIF('Cap 3'!J2:J35,"A*") | D5: =COUNTIF('Cap 3'!M2:M35,"sim")
A6: Cap 4 | B6: =COUNTA('Cap 4'!A2:A41) | C6: =COUNTIF('Cap 4'!J2:J41,"A*") | D6: =COUNTIF('Cap 4'!M2:M41,"sim")
A7: Cap 5 | B7: =COUNTA('Cap 5'!A2:A37) | C7: =COUNTIF('Cap 5'!J2:J37,"A*") | D7: =COUNTIF('Cap 5'!M2:M37,"sim")
A8: Cap 6 | B8: =COUNTA('Cap 6'!A2:A28) | C8: =COUNTIF('Cap 6'!J2:J28,"A*") | D8: =COUNTIF('Cap 6'!M2:M28,"sim")
A9: Cap 7 | B9: =COUNTA('Cap 7'!A2:A37) | C9: =COUNTIF('Cap 7'!J2:J37,"A*") | D9: =COUNTIF('Cap 7'!M2:M37,"sim")
A10: Cap 8 | B10: =COUNTA('Cap 8'!A2:A39) | C10: =COUNTIF('Cap 8'!J2:J39,"A*") | D10: =COUNTIF('Cap 8'!M2:M39,"sim")
A11: Total | B11: =SUM(B2:B10) | C11: =SUM(C2:C10) | D11: =SUM(D2:D10)
A13: Pendências abertas | B13: =COUNTA(Pendências!A2:A60)-COUNTA(Pendências!F2:F60)
A14: Perguntas (rascunho) | B14: =COUNTA(Perguntas!A2:A26)
A15: Provas com FALTA na casa 6 | B15: =COUNTIF('Provas e cobertura'!F2:F24,"FALTA")
A16: Mudanças no docx (para a revisão 3) | B16: =COUNTA('Mudanças no docx'!A2:A60)

Sheet Partidas
A1: Partida | B1: Impostor (sempre do sistema) | C1: Ajudante (A2) | D1: Falso culpado | E1: Casa mínima | F1: Lugares para humanos (casa − impostor) | G1: Onde disse estar na janela (A5) | H1: Quem o viu não estar (A5) | I1: Rastros (A3, A6, A7) | J1: Origem dos R$ 96.000 (A8) | K1: Confissão (A9)
A2: S | B2: O Subgerente | C2: O Caixa Veterano (inconsciente: assinou o malote sem contar) | D2: O Técnico | E2: 8 | F2: casa 8: 7; casa 10: 9; casa 12: 11; casa 13: 12 | G2: Nos Guichês, buscando a guia | H2: Câmera 2 (só o mostra às 8h00:05); reforço: Estagiária | I2: fita no indicador (A3), farinha na barra (A6), cartão do rádio (A7) | J2: joias da família empenhadas (A8) | K2: Texto público do Cap. 8 (versão de referência)
A3: G | B3: O Gerente | C3: O Subgerente (inconsciente: assinou o malote sem contar) | D3: O Técnico | E3: 8 | F3: casa 8: 7; casa 10: 9; casa 12: 11; casa 13: 12 | G3: "Ao telefone" | H3: Ramal da Gerência sem chamada entre 7h50 e 8h10; câmera 1 o mostra entrando na divisória às 7h57:50 | I3: fita (A3: tabela diz indicador, Variante G diz indicador), farinha (A6), cartão (A7) | J3: resgate antecipado da previdência privada (A8) | K3: Variante G, no fim do Cap. 8
A4: V | B4: O Caixa Veterano | C4: O Subgerente (inconsciente: assinou o malote sem contar) | D4: O Técnico | E4: 8 | F4: casa 8: 7; casa 10: 9; casa 12: 11; casa 13: 12 | G4: "Na Mesa" | H4: Câmera 2 mostra a Mesa vazia até 8h00:02; reforço: Segurança do Veículo | I4: fita no indicador (A3), farinha (A6), cartão (A7) | J4: economias guardadas para a aposentadoria (A8) | K4: Variante V, no fim do Cap. 8
A6: Fixo nas três partidas
A7: Falso culpado (fixo) | B7: O Técnico — conta admin.local, chave da porta lateral, passagem, "no Rack", atualização que travou o sistema. Exclusão na virada do fim do Cap. 6: Segurança Interno + registro do aplicativo de entregas (7h58:51); reforço: fotografias do Padeiro.
A8: Ajudantes involuntários (fixos) | B8: Segurança Interno (rádio fora do carregador), Segurança do Veículo (conferiu o lacre pela tela), Funcionário da Limpeza (transformou o descarte em cena).
A9: Encobrimento (fixo) | B9: O Gerente, às 8h31, encosta um cabo na grade quente do exaustor do Rack (curto às 8h51) para apagar o ajuste_96. Na partida G é encobrimento e autoria.
A10: O oculto (fixo) | B10: O Monitor Remoto: denúncia anônima, mensagem das 8h10, reimpressão das 8h35, mensagem do epílogo. Nunca aparece, nunca é o impostor, nunca é humano.
A11: O vigia de fora (fixo) | B11: O Operador de Rádio: antecipação das 6h52, canal fechado às 7h49, registro bruto das 8h29, contagem das 9h31, suprimento à 0392 (9h56). Não mente; nunca é humano.
A12: Pistas menores (fixas) | B12: Estagiária (senha e cópia da 17-B), Funcionário da Limpeza (chave e saco no chão), Operadora (esmalte), Caixa Novato (pasta, pânico, banheiro).
A13: Ato do impostor (fixo nas 3) | B13: 8 dias antes percebe a duplicidade e cala; 5 dias antes agenda saque de R$ 96.000 na 0392; véspera 15h50 lacra o malote 41 com R$ 384.000 sob guia de R$ 480.000; 16h30 retira os R$ 96.000; 6h28–7h06 entra pela porta lateral, guarda o dinheiro na caixa de 1998, pede a antecipação (6h52), troca o lacre no registro (6h58), afrouxa o conector da câmera 3; 7h57:55 pareia o rádio; 7h58:05 ordem falsa; troca pela passagem; volta à Gerência às 7h59:54.

Sheet Ajustes A1–A10
A1: Ponto | B1: Partida S — Subgerente (referência) | C1: Partida G — Gerente | D1: Partida V — Caixa Veterano | E1: Observação
A2: A1. Quem percebeu a duplicidade oito dias antes, e como | B2: Ao reler o espelho do reprocessamento | C2: Ao assinar o balancete semanal do Cofre | D2: Ao refazer de cabeça a soma do frigorífico
A3: A2. Malote 41 na véspera, 15h50: quem contou e lacrou; quem assinou sem contar (o ajudante) | B3: Contou o Subgerente; assinou o Caixa Veterano | C3: Contou o Gerente; assinou o Subgerente | D3: Contou o Caixa Veterano; assinou o Subgerente
A4: A3. O corte coberto por fita microporosa estreita (1,2 cm) | B4: No indicador do Subgerente | C4: No indicador do Gerente | D4: No indicador do Caixa Veterano | E4: DECIDIDO 05/10: indicador nas três partidas (o docx ainda diz polegar).
A5: A4. Na Gerência, às 7h57:50 | B5: O Caixa Veterano assina primeiro e sai para a Mesa; o Subgerente fica “para fechar o livro” | C5: Os dois assinam e saem; o Gerente deixa a Auditora “para um telefonema” e entra | D5: O Subgerente assina primeiro e sai para os Guichês; o Caixa Veterano fica
A6: A5. Onde disse estar na janela, e quem o viu não estar | B6: “Nos Guichês, buscando a guia”: a câmera 2 só o mostra às 8h00:05 (reforço: a Estagiária) | C6: “Ao telefone”: o ramal da Gerência não tem chamada entre 7h50 e 8h10, e a câmera 1 o mostra entrando na divisória às 7h57:50 | D6: “Na Mesa”: a câmera 2 mostra a Mesa vazia até 8h00:02 (reforço: o Segurança do Veículo)
A7: A5b. Álibis dos dois inocentes | B7: Gerente na Porta Giratória (Auditora, Cliente, câmera 1); Caixa Veterano na Mesa (câmera 2) | C7: Subgerente nos Guichês (câmera 2); Caixa Veterano na Mesa (câmera 2) | D7: Gerente na Porta Giratória (Auditora, Cliente, câmera 1); Subgerente nos Guichês (câmera 2)
A8: A6. Farinha seca na barra da calça | B8: Do Subgerente | C8: Do Gerente | D8: Do Caixa Veterano
A9: A7. Dígitos completos do cartão que pareou o rádio | B9: Do Subgerente | C9: Do Gerente | D9: Do Caixa Veterano
A10: A8. Titular do saque e origem do dinheiro | B10: Subgerente: joias da família empenhadas para cobrir o saque | C10: Gerente: resgate antecipado da previdência privada | D10: Caixa Veterano: as economias guardadas para a aposentadoria
A11: A9. Confissão e motivo (Cap. 8) | B11: Texto público | C11: Variante G, no fim do Cap. 8 | D11: Variante V, no fim do Cap. 8
A12: A10. O impostor no epílogo | B12: Sai acompanhado; deixa a fita no balcão | C12: Tira o anel, deixa o crachá na mesa e sai acompanhado | D12: Pendura a fotografia de volta e sai acompanhado
A13: A5-G4 | B13: Declaração do Gerente no Cap. 4 (não marcada no texto): "Diante da Porta Giratória, com a Auditora e a Cliente" (verdade) | C13: "Ao telefone" (mentira) | D13: "Diante da Porta Giratória" (verdade) | E13: APLICADO 05/10 (jogo, Cap. 4: declarações; Cap. 7: gavetas). Marcar A5 no docx.
A14: A5-crachá | B14: Crachá de chegada citado na revelação (Cap. 8): 7h16 (Subgerente) | C14: 7h12 (Gerente) | D14: 7h21 (Caixa Veterano) | E14: APLICADO 05/10 (jogo, Cap. 8). Marcar A5 no docx.
A15: Ordem falsa | B15: Voz da ordem "Porta lateral. Possível tentativa." (Cap. 2): Subgerente | C15: Gerente | D15: Caixa Veterano | E15: O texto é fixo e a voz é irreconhecível; nenhuma mudança de texto, só registro.

Sheet Elenco
A1: id | B1: Personagem | C1: Função | D1: Bloco | E1: Entra a partir da casa | F1: Pode ser humano? | G1: Candidato a impostor? | H1: Canal | I1: Quem é | J1: Por que está ali | K1: Segredo inocente | L1: Rastro | M1: Voz | N1: "Nunca diria" (limite das 6 versões) | O1: O que vê | P1: O que tem a perder | Q1: Personalidade (Big Five) | R1: Curiosidade (5DC)
A2: auditora | B2: A Auditora | C2: O olhar de fora | D2: Núcleo | E2: 6 | F2: Sim | G2: Não | H2: presencial | I2: auditora de custódia da regional. | J2: a auditoria surpresa exige alguém sem vínculo com a agência. | K2: já reprovou a gestão do Gerente em outra agência, o que a faz parecer movida por vingança; tem um guarda-chuva de cabo claro e comprou café na padaria às 7h38. | L2: perfume cítrico, grafite nas margens, farinha na ponteira do guarda-chuva. | M2: perguntas curtas ("Fato ou interpretação?"); nunca promete certeza antes da prova. | N2: nunca promete certeza antes da prova | O2: da Porta Giratória, a divisória da Gerência e as silhuetas atrás dela; antes de rostos, assinaturas. | P2: a identidade de profissional justa. | Q2: muito consciente, pouco expansiva, moderadamente afável, aberta a hipóteses, vulnerável ao medo de errar; honesta a ponto de não suavizar conclusões, lenta na humildade. Sob pressão, transforma afeto em método. | R2: explora detalhes com prazer, não abandona lacunas, suporta bem o desconhecido, escuta escolhas de palavras, evita riscos físicos.
A3: caixa_veterano | B3: O Caixa Veterano | C3: O laço de sangue | D3: Núcleo | E3: 6 | F3: Sim, exceto na partida V | G3: Sim (V) | H3: presencial | I3: tesoureiro há vinte e sete anos, o arquivo vivo da agência. | J3: integra a dupla de abertura do Cofre e a escala de fechamento. | K3: tirou da parede uma fotografia antiga da equipe e pretende pedir transferência; onze dias antes, assinou a consolidação sem recontar o Cofre para ir ao velório de um ex-colega. | L3: pó de talco das luvas nas cédulas. | M3: fala por lembranças ("Antigamente, isso tinha outro ruído"); nunca acusa sem antes refazer uma conta. | N3: nunca acusa sem antes refazer uma conta | O3: o que mudou, porque lembra do que costumava estar ali. | P3: o nome limpo e a aposentadoria. | Q3: consciente, reservado, afável por hábito, pouco aberto a mudanças, vulnerável à culpa; honesto, mas a humildade falha quando a experiência é contestada. | R3: sente prazer em diferenças mínimas, persegue contas incompletas, tolera mal o desconhecido, escuta sem invadir, evita riscos.
A4: tecnico | B4: O Técnico | C4: Quem conhece a estrutura | D4: Núcleo | E4: 6 | F4: Sim (preferência: é o falso culpado) | G4: Não (falso culpado fixo) | H4: presencial | I4: prestador de manutenção de rede e câmeras. | J4: chamado pelo Erro 17 às 7h25; chegou às 7h40 pela porta lateral. | K4: usa peças reaproveitadas sem nota; às 7h55 saiu pela porta lateral para receber uma delas de um motoboy e mente que estava no Rack durante a janela. | L4: cheiro de estanho, limalha no punho, fita isolante em dois dedos. | M4: fala em causas, nunca em culpas; jamais chama improviso de solução. | N4: nunca em culpas | O4: às 7h45, o conector da câmera 3 puxado e a poeira do fundo do Rack riscada em arco. | P4: o contrato e o sustento. | Q4: aberto a mecanismos, muito consciente no diagnóstico, pouco expansivo, direto a ponto de parecer hostil, ansioso quando tocam suas ferramentas; honesto sobre resultados, pouco humilde sobre método. | R4: explora sistemas, não larga uma falha sem origem, tolera a incerteza técnica, lê mal intenções, aceita riscos que pode medir.
A5: operadora | B5: A Operadora da Central | C5: O registro | D5: Núcleo | E5: 6 | F5: Sim | G5: Não | H5: presencial (Central, interfone) | I5: operadora das câmeras e do rádio. | J5: conserva chamadas, horários e imagens. | K5: na noite anterior, depois de testar o rádio às 19h12, ouviu uma discussão do Gerente com o Subgerente e apagou a linha da ocorrência; às 7h43 anotou a piscada da câmera 3 num bloco particular. | L5: lascas de esmalte lilás no botão do rádio. | M5: "No canal, ficou assim"; nunca diz que uma gravação explica um motivo. | N5: nunca diz que uma gravação explica um motivo | O5: dezesseis quadros, respirações e silêncios. | P5: a carreira. | Q5: consciente, introvertida, moderadamente aberta, afável com quem respeita limites, tensa diante do confronto; honesta, mas cede quando privacidade e dever colidem. | R5: distingue vozes, persegue lacunas de horário, suporta o desconhecido enquanto pode arquivá-lo, alta curiosidade social, baixa busca por emoção.
A6: gerente | B6: O Gerente | C6: A autoridade | D6: Núcleo | E6: 6 | F6: Sim, exceto na partida G | G6: Sim (G) | H6: presencial | I6: responsável pela agência. | J6: recebe a auditoria e trava a agência. | K6: onze dias antes, saiu às 19h00 para encontrar quem ameaçava denunciar um favorecimento numa concessão de crédito e autorizou o fechamento por telefone; às 8h31 queima o cabo do Rack (encobrimento, fixo). | L6: loção amadeirada; marcas quadradas do anel nos papéis. | M6: fala no plural ("Nós seguiremos o protocolo"); nunca admite descontrole diante da equipe. | N6: nunca admite descontrole diante da equipe | O6: condutas antes de evidências. | P6: o cargo e o nome. | Q6: consciente com hierarquias, expansivo quando comanda, pouco aberto a contestação, cordial por conveniência, instável quando perde autoridade; a honestidade enfraquece diante da ameaça à instituição. | R6: pouca exploração; a dúvida só cresce quando afeta sua posição; tolera mal a incerteza; lê bem relações; aceita riscos de reputação.
A7: cliente_cofre | B7: A Cliente do Cofre | C7: O conhecedor do acervo | D7: Núcleo | E7: 6 | F7: Sim | G7: Não | H7: presencial | I7: filha do engenheiro que construiu o prédio da agência em 1987. | J7: veio retirar do cofre alugado cartas e a planta original da obra. | K7: as cartas mostram que o pai recebeu pagamento por fora para construir uma passagem que não constaria da planta oficial; ela quer proteger o nome dele. Na véspera, às 15h55, esperava na Antecâmara e viu o malote 41 cheio na plataforma, com um vinco diagonal. | L7: fios de lã vermelha, cheiro de cânfora. | M7: fala baixo, com datas impecáveis; nunca reduz uma lembrança a preço. | N7: nunca reduz uma lembrança a preço | O7: vincos, procedências, gestos herdados; da Porta Giratória, quantas silhuetas entram e saem da Gerência; barras e bainhas. | P7: a memória da família. | Q7: aberta a histórias, organizada, reservada, seletivamente afável, ansiosa quando a intimidade é ameaçada; preserva a verdade, mas controla o momento. | R7: explora objetos, insiste em lacunas biográficas, tolera mal a exposição, forte curiosidade social, baixa busca por emoção.
A8: subgerente | B8: O Subgerente | C8: O guardião do rito | D8: 1º bloco | E8: 8 | F8: Sim, exceto na partida S | G8: Sim (S, referência) | H8: presencial | I8: responsável pelos procedimentos, horários e assinaturas da tesouraria. | J8: integra a dupla de abertura e a escala de fechamento. | K8: onze dias antes, reprocessou a fila que duplicou o depósito e, desde então, desconfia de algo; às 7h35, pediu a chave 17-B ao Funcionário da Limpeza para tirar do armário do Arquivo o espelho daquele reprocessamento e relê-lo antes da auditoria. | L8: papel térmico entre os dedos, cheiro quase apagado de chuva. | M8: cortesia precisa; oferece soluções antes que peçam; nunca diz "não sei". | N8: nunca diz "não sei" | O8: a agência como sistema que pode ser corrigido. | P8: a identidade profissional e o cargo. | Q8: extremamente consciente, reservado, pouco aberto a perder o controle, cordial por estratégia, instável diante da vergonha. | R8: explora mecanismos com habilidade, persegue obsessivamente problemas sem solução, tolera alto estresse, lê as vulnerabilidades dos colegas, aceita riscos crescentes para preservar a aparência.
A9: limpeza | B9: O Funcionário da Limpeza | C9: Quem cuida da rotina | D9: 1º bloco | E9: 8 | F9: Sim | G9: Não | H9: presencial | I9: conhece o prédio pela sola, pelos cheiros e pelo lugar exato de cada objeto. | J9: chega às 7h10 e limpa antes da abertura. | K9: emprestou a chave 17-B ao Subgerente das 7h35 às 7h47, para quitar uma cadeia de favores (um adiantamento para a cirurgia da irmã); às 8h01 tirou o saco do cesto e o largou no chão. | L9: cheiro de eucalipto, semicírculo de água limpa, a roda do balde que range. | M9: fala por objetos ("Isso não estava aqui"); nunca comenta conversa entreouvida. | N9: nunca comenta conversa entreouvida | O9: às 7h46, o Arquivo limpo, o cesto vazio e a caixa de 1998 dois dedos para fora. | P9: o emprego. | Q9: consciente com o espaço, discreto, muito afável, ansioso diante da autoridade; honesto, com uma humildade explorada como submissão. | R9: nota mudanças concretas, insiste em coisas fora do lugar, age diante do desconhecido, ouve sem parecer ouvir, evita riscos.
A10: seguranca_veiculo | B10: O Segurança do Veículo | C10: O intérprete das regras | D10: 2º bloco | E10: 10 | F10: Sim | G10: Não | H10: presencial (Eclusa) e rádio | I10: responsável pela custódia na Eclusa. | J10: chega com o carro-forte. | K10: a certificação vence naquela semana; às 8h00, com pressa e diante da auditoria, conferiu o lacre pela tela da Mesa, e não pela via de papel, onde constava ML-8842. | L10: fibras negras do colete. | M10: fala por proibições ("Sem dupla conferência, não atravessa"); nunca diz que uma regra está errada. | N10: nunca diz que uma regra está errada | O10: da Eclusa, pelo vidro, a Mesa de Recebimento. | P10: o emprego. | Q10: consciente, reservado, pouco aberto a exceções, cooperativo com ordens claras, tenso diante de autoridades incompatíveis; honesto, mas o medo do posto reduz a coragem de contestar. | R10: pouca exploração, insiste até fechar divergências de protocolo, suporta perigo concreto, lê mal o subtexto.
A11: padeiro | B11: O Padeiro | C11: Quem conhece o exterior | D11: 2º bloco | E11: 10 | F11: Sim | G11: Não | H11: só telefone (fora da agência) | I11: dono da padaria da esquina oposta. | J11: abre antes das cinco; a porta de serviço dá para a rua de trás, de frente para a porta lateral da agência. | K11: vende café pela porta de serviço antes do horário licenciado, por isso hesita em entregar imagens. | L11: farinha nos sapatos; os sacos empilhados na porta de serviço sujam a barra de quem passa. | M11: mede o tempo por fornadas ("Foi depois do segundo pão"); nunca descreve um rosto que não viu. | N11: nunca descreve um rosto que não viu | O11: às 6h28, uma figura de capa atravessando sua porta de serviço com uma sacola; pela câmera, a porta lateral às 6h36, às 7h06, às 7h58:47 e às 7h59:51; nunca rostos sob guarda-chuva. | P11: a licença. | Q11: observador, disciplinado pela rotina, sociável com clientes, pouco ansioso diante do que é distante; honesto, mas teme que a verdade exponha o próprio desvio. | R11: explora mudanças da rua, persegue discrepâncias de horário, evita riscos.
A12: farmaceutica | B12: A Farmacêutica | C12: Quem conhece o consumo | D12: 3º bloco | E12: 12 | F12: Sim | G12: Não | H12: presencial | I12: farmacêutica do plantão da esquina. | J12: às 7h50 atravessa para entregar discretamente um calmante ao Caixa Novato. | K12: forneceu o calmante sem receita; às 6h31 vendeu luvas tamanho G e fita microporosa a uma figura de capa e guarda-chuva de cabo claro, que pagou em dinheiro. | L12: álcool em gel com lavanda. | M12: fala em quantidades ("Quanto havia? Quanto falta?"); nunca culpa quem está em crise. | N12: nunca culpa quem está em crise | O12: da Porta Giratória, quantas silhuetas entram e saem da Gerência; curativos, respirações, tremores. | P12: a licença. | Q12: atenta, organizada, sociável sem intimidade, muito afável, vulnerável à culpa; honesta, mas cede quando uma regra ameaça alguém em sofrimento. | R12: sinais corporais, insiste até compreender uma discrepância, tolera emergências, alta curiosidade social.
A13: estagiaria | B13: A Estagiária | C13: Quem conhece os sistemas | D13: 3º bloco | E13: 12 | F13: Sim | G13: Não | H13: presencial | I13: estagiária que alimenta planilhas e telas. | J13: imprime etiquetas e organiza as pastas da Mesa. | K13: anotou num papel a senha admin.local, ditada numa pane, e mandou copiar a chave 17-B depois de ficar presa no corredor; os dois estão na pasta azul trocada com a do Caixa Novato às 7h52. | L13: tinta de caneta na lateral da mão. | M13: fala depressa quando sabe e devagar quando teme; nunca admite de imediato que uma descoberta começou por curiosidade. | N13: nunca admite de imediato que uma descoberta começou por curiosidade | O13: dos Guichês, quem chega ou não chega à Mesa; reconhece o pulsar do estabilizador da Gerência. | P13: a chance de ficar. | Q13: muito aberta, aplicada, expansiva quando domina o assunto, cooperativa, ansiosa por não parecer incapaz. | R13: explora sistemas, persegue lacunas até a exaustão, tolera mal a incerteza social, observa reações, aceita riscos digitais.
A14: transportador | B14: O Transportador | C14: A testemunha técnica | D14: Completa | E14: 13 | F14: Sim | G14: Não | H14: rádio (carro-forte) | I14: move os malotes dentro do carro-forte. | J14: recebe o malote 41 na Eclusa. | K14: uma hérnia que o faz alternar as mãos. | L14: graxa clara nos fechos. | M14: fala só do que tocou ("Pesava como o declarado"); nunca opina sobre pessoas. | N14: nunca opina sobre pessoas | O14: lacres, alças, peso, esforço. | P14: o sustento da família. | Q14: disciplinado, reservado, cooperativo, inquieto quando o corpo ameaça denunciá-lo. | R14: diferenças de peso e equilíbrio, baixa curiosidade social.
A15: monitor_remoto | B15: O Monitor Remoto | C15: O oculto | D15: Sempre (sistema) | E15: toda casa | F15: Nunca | G15: Nunca | H15: mensagem sem origem; reimpressão remota | I15: operador da central de segurança regional; nunca aparece. | J15: vê as câmeras da 0688 à distância e tem acesso remoto de suporte à rede da agência. | K15: onze dias antes, às 19h20, silenciou sem registrar o alerta "fechamento sem contagem física", porque estava fora do posto. | L15: nenhum físico; mensagens sem identificação e a origem "rede de segurança regional" na reimpressão das 8h35. | M15: frases curtas, sem sujeito ("Procurem quem abriu antes"); nunca diz o próprio nome nem a palavra "eu". | N15: nunca diz o próprio nome nem a palavra "eu" | O15: imagens e sensores, nunca o que acontece fora das câmeras. | P15: o posto. | Q15: consciente, solitário, culpado, mais corajoso no anonimato do que diante de alguém. | R15: observação paciente, sensibilidade à privação alta.
A16: operador_radio | B16: O Operador de Rádio | C16: O vigia de fora | D16: Sempre (sistema) | E16: toda casa | F16: Nunca | G16: Nunca | H16: rádio da base | I16: operador da base da transportadora; nunca entra na agência. | K16: autorizou a antecipação das 6h52 com confirmação incompleta. | L16: registros digitais e pausas da voz. | M16: horários e protocolos ("Confirme origem e destino"); nunca transforma suposição em identificação. | N16: nunca transforma suposição em identificação | O16: horários, códigos, rotas e suprimentos, nunca rostos nem motivos. | P16: a função. | Q16: consciente, estável sob pressão, cooperativo; demora a admitir a própria falha.
A17: motorista | B17: O Motorista | C17: Apoio | D17: Apoio (sistema) | E17: toda casa | F17: Nunca | G17: Não | H17: rádio (carro-forte) | I17: Conduz o carro-forte. | K17: Uma filha prestando vestibular e uma advertência guardada por ter aceitado outra alteração sem confirmação dupla. | M17: Fala depois de consultar a prancheta ("O que vale é o carimbo").
A18: seguranca_interno | B18: O Segurança Interno | C18: Apoio | D18: Apoio (sistema) | E18: toda casa | F18: Nunca | G18: Não | H18: presencial | I18: Guarda o Corredor Restrito. | K18: Às 7h20 testou o rádio reserva na Gerência, ouviu uma respiração no canal e deixou o aparelho fora do carregador. Na janela, foi à porta lateral pela ordem falsa e viu, pelo vidro, um homem de capa, de costas, com um motoboy. | L18: O couro do coldre range quando ele se vira.
A19: caixa_novato | B19: O Caixa Novato | C19: Apoio | D19: Apoio (sistema) | E19: toda casa | F19: Nunca | G19: Não | H19: presencial | I19: Caixa novo; conta cédulas movendo os lábios. | K19: Esconde a crise de ansiedade e o calmante sem receita. Usa no indicador uma tira larga de fita microporosa do kit da Gerência. Às 7h52 trocou de pasta com a Estagiária; na janela estava no banheiro, de onde ouviu a parede raspar duas vezes; às 8h02 abriu o Arquivo Morto. | L19: Fita larga (2,5 cm) encardida no indicador.

Sheet Casas
A1: Casa | B1: Composição | C1: Personagens jogáveis | D1: Quem está | E1: Sempre presentes (sistema) | F1: Partidas que cabem | G1: Máx. humanos
A2: 6 | B2: Núcleo | C2: 6 | D2: A Auditora, O Caixa Veterano, O Técnico, A Operadora da Central, O Gerente, A Cliente do Cofre | E2: Monitor Remoto (oculto), Operador de Rádio (vigia), Motorista, Segurança Interno, Caixa Novato | F2: nenhuma (todas pedem casa 8) | G2: 5
A3: 8 | B3: Núcleo + 1º bloco | C3: 8 | D3: A Auditora, O Caixa Veterano, O Técnico, A Operadora da Central, O Gerente, A Cliente do Cofre, O Subgerente, O Funcionário da Limpeza | E3: Monitor Remoto (oculto), Operador de Rádio (vigia), Motorista, Segurança Interno, Caixa Novato | F3: S, G, V | G3: 7
A4: 10 | B4: + 2º bloco | C4: 10 | D4: A Auditora, O Caixa Veterano, O Técnico, A Operadora da Central, O Gerente, A Cliente do Cofre, O Subgerente, O Funcionário da Limpeza, O Segurança do Veículo, O Padeiro | E4: Monitor Remoto (oculto), Operador de Rádio (vigia), Motorista, Segurança Interno, Caixa Novato | F4: S, G, V | G4: 9
A5: 12 | B5: + 3º bloco | C5: 12 | D5: A Auditora, O Caixa Veterano, O Técnico, A Operadora da Central, O Gerente, A Cliente do Cofre, O Subgerente, O Funcionário da Limpeza, O Segurança do Veículo, O Padeiro, A Farmacêutica, A Estagiária | E5: Monitor Remoto (oculto), Operador de Rádio (vigia), Motorista, Segurança Interno, Caixa Novato | F5: S, G, V | G5: 11
A6: 13 | B6: Casa cheia (+ Transportador) | C6: 13 | D6: A Auditora, O Caixa Veterano, O Técnico, A Operadora da Central, O Gerente, A Cliente do Cofre, O Subgerente, O Funcionário da Limpeza, O Segurança do Veículo, O Padeiro, A Farmacêutica, A Estagiária, O Transportador | E6: Monitor Remoto (oculto), Operador de Rádio (vigia), Motorista, Segurança Interno, Caixa Novato | F6: S, G, V | G6: 12

Sheet Linha do tempo
A1: Dia | B1: Hora | C1: Onde | D1: Quem | E1: O quê | F1: Como se sabe (fonte) | G1: Revelado no cap. | H1: Fixo / ajuste
A2: Onze dias antes | B2: 18h54 | C2: Guichê 2 | D2: Caixa Veterano | E2: Depósito do frigorífico de R$ 96.000, recibo único | F2: Recibo (Caixa Veterano); consolidações (Operadora) | G2: 5 | H2: Fixo
A3: Onze dias antes | B3: 19h00 | C3: — | D3: Gerente | E3: Sai para encontrar quem ameaçava denunciar favorecimento; autoriza o fechamento por telefone | F3: ajuste_96 ("G sai"); confissão do Gerente | G3: 6 | H3: Fixo
A4: Onze dias antes | B4: 19h03 | C4: Terminal (acesso remoto) | D4: Técnico | E4: Sistema congela durante atualização remota (admin.local) | F4: Registro do sistema (Operadora); Técnico admite | G4: 5 | H4: Fixo
A5: Onze dias antes | B5: 19h11 | C5: Terminal | D5: Subgerente | E5: Reprocessa manualmente a fila: o depósito entra duas vezes | F5: Consolidações; ajuste_96; Subgerente confirma | G5: 5–6 | H5: Fixo
A6: Onze dias antes | B6: 19h12 | C6: Central / Gerência | D6: Operadora | E6: Testa o rádio | F6: Operadora (Cap. 2) | G6: 2 | H6: Fixo
A7: Onze dias antes | B7: 19h20 | C7: Cofre | D7: Subgerente e Caixa Veterano | E7: Consolidação assinada sem recontagem física (Veterano vai ao velório) | F7: ajuste_96; confissão do Veterano | G7: 6 | H7: Fixo
A8: Onze dias antes | B8: 19h20 | C8: Central regional | D8: Monitor Remoto | E8: Alerta "fechamento sem contagem física"; fora do posto, silencia sem registrar | F8: Mensagem do epílogo | G8: 8 (epílogo) | H8: Fixo
A9: Oito dias antes | B9: — | C9: — | D9: Impostor | E9: Percebe a duplicidade e cala | F9: Confissão | G9: 8 | H9: A1
A10: Cinco dias antes | B10: — | C10: Agência 0392 | D10: Impostor | E10: Agenda saque em espécie de R$ 96.000 (recursos próprios) | F10: Regional, pela Auditora (10h41) | G10: 7 | H10: A8
A11: Véspera | B11: 15h50 | C11: Cofre / Antecâmara | D11: Impostor + cossignatário | E11: Malote 41 lacrado com R$ 384.000 sob guia de R$ 480.000; o cossignatário assina sem contar | F11: Livro de lacres (Operadora) | G11: 7 | H11: A2
A12: Véspera | B12: 15h55 | C12: Antecâmara | D12: Cliente do Cofre | E12: Vê o malote 41 cheio na plataforma, com vinco diagonal | F12: Cliente do Cofre | G12: 1 | H12: Fixo
... A74: Manhã seguinte | B74: 8h10 | C74: Central | D74: Monitor Remoto | E74: "Onze dias atrás. Dezenove e vinte. Alarme de fechamento sem contagem. Posto vazio. Silenciado depois. Por isso a auditoria." | F74: — | G74: 8 (epílogo) | H74: Fixo

Sheet Janela 87 s
A1: A janela crítica, segundo a segundo (ordem às 7h58:05; câmera 3 cega de 7h58:12 a 7h59:39)
A3: +s desde a ordem | B3: Hora | C3: O que acontece | D3: Fonte
A4: +0 | B4: 7h58:05 | C4: Ordem falsa pelo rádio: "Porta lateral. Possível tentativa." O Segurança Interno corre à porta lateral | D4: Gravação (Operadora, 8h18)
A5: +1 | B5: 7h58:06 | C5: Impostor sai da Gerência pela passagem — 1º raspado do painel (ouvido do banheiro) | D5: Caixa Novato
A6: +7 | B6: 7h58:12 | C6: Câmera 3 cai (vibração do exaustor completa a queda) | D6: Central; microfone (estalo)
A7: +16 | B7: 7h58:21 | C7: Impostor no interior do Rack | D7: Rota (cânone)
A8: +20 | B8: 7h58:25 | C8: Impostor entra no Arquivo Morto; pega a caixa de 1998 e o saco reserva | D8: Rota
A9: +42 | B9: 7h58:47 | C9: Padeiro (câmera da porta de serviço): o Técnico recebe a caixa do motoboy | D9: Fotografia do Padeiro
A10: +46 | B10: 7h58:51 | C10: Aplicativo de entregas registra a entrega ao Técnico | D10: App do Técnico (Cap. 6)
A11: ~+25…+65 | B11: 7h58:31–7h59:11 | C11: Na Antecâmara: troca de 40 s (abre ML-8842, passa 6 blocos + 2, fecha com ML-8847 e etiqueta); corta a mão na grapa através da luva | D11: Simulação (Cap. 4); luva (Cap. 6)
A12: +79 | B12: 7h59:24 | C12: Tampa metálica do cesto de descarte bate (saco ML-8842 e luva rasgada) | D12: Microfone da Central (Operadora, Cap. 5)
A13: +94 | B13: 7h59:39 | C13: Impostor recoloca o conector; câmera 3 volta | D13: Central
A14: +106 | B14: 7h59:51 | C14: Técnico volta empurrando a porta lateral (sensor: fechada) | D14: Sensor; fotografia do Padeiro
... A21: — | B21: 8h03 | C21: Gerente trava a Porta Giratória | D21: Todos

Sheet Postos na janela
A1: Personagem | B1: Partida S | C1: Partida G | D1: Partida V | E1: Quem o situa (exclusão)
A2: A Auditora | B2: Porta Giratória | C2: Porta Giratória (o Gerente a deixa às 7h57:50) | D2: Porta Giratória | E2: Câmera 1; Cliente e Farmacêutica
A3: O Gerente | B3: Porta Giratória | C3: IMPOSTOR: Gerência → passagem → Rack → Arquivo → Antecâmara (diz "ao telefone") | D3: Porta Giratória | E3: S/V: Auditora, Cliente, câmera 1 (A5b)
A4: O Subgerente | B4: IMPOSTOR: Gerência → passagem… (diz "nos Guichês") | C4: Guichês | D4: Guichês | E4: G/V: câmera 2 (A5b)
A5: O Caixa Veterano | B5: Mesa de Recebimento | C5: Mesa de Recebimento | D5: IMPOSTOR: Gerência → passagem… (diz "na Mesa") | E5: S/G: câmera 2; Segurança do Veículo (A5b)
A6: A Cliente do Cofre | B6: Porta Giratória | C6: Porta Giratória | D6: Porta Giratória | E6: Câmera 1
A7: A Farmacêutica | B7: Porta Giratória | C7: Porta Giratória | D7: Porta Giratória | E7: Câmera 1
A8: A Operadora da Central | B8: Central (console, mão no rádio) | C8: idem | D8: idem | E8: Câmera interna da Central
A9: O Técnico | B9: Rua de trás, com o motoboy (diz "no Rack") | C9: idem | D9: idem | E9: Segurança Interno; app de entregas 7h58:51; fotografias do Padeiro
A10: O Funcionário da Limpeza | B10: Saguão, com o balde | C10: idem | D10: idem | E10: Câmera 1
A11: A Estagiária | B11: Guichês | C11: idem | D11: idem | E11: Câmera 2
A12: O Caixa Novato | B12: Banheiro dos Funcionários (diz "almoxarifado", depois admite) | C12: idem | D12: idem | E12: Ninguém o vê (banheiro sem câmera); só o raspado da parede o situa
... A19: O Monitor Remoto | B19: Central regional (vê a câmera 3 cair) | C19: idem | D19: idem | E19: Fora da agência

Sheet Perspectivas
A1: Momento | B1: Personagem | C1: Onde estava | D1: O que percebeu | E1: O que concluiu
A2: 7h57:40 a 7h57:55, a Gerência | B2: (vários) | D2: A Cliente do Cofre conta dois entrando e um saindo **A4**, e a Farmacêutica confirma. A câmera 1 registra o mesmo. A Auditora vê silhuetas e não as distingue. O Segurança do Veículo vê quem chega à Mesa **A4**.
A3: 7h53, a impressora da Gerência | B3: (vários) | D3: A Auditora, na Porta Giratória, ouve um gemido atrás da divisória e anota sem saber por quê. A Estagiária, nos Guichês, reconhece o som e conclui que alguém imprimiu uma etiqueta. O Caixa Veterano e o Subgerente, na Antecâmara, não ouvem. O Gerente, ao lado da Auditora, ouve e não comenta.
A4: 7h58:05–7h59:39 (a janela) | B4: Auditora | C4: Porta Giratória | D4: A mudança simultânea de atenção quando o rádio chamou | E4: Algo foi provocado
A5: 7h58:05–7h59:39 (a janela) | B5: Gerente | C5: Porta Giratória A5b | D5: A ordem pelo rádio do Segurança Interno | E5: Desorganização da equipe
A6: 7h58:05–7h59:39 (a janela) | B6: Farmacêutica | C6: Porta Giratória | D6: A Gerência com uma pessoa dentro A4 | E6: Nada, ainda
A7: 7h58:05–7h59:39 (a janela) | B7: Cliente do Cofre | C7: Porta Giratória | D7: Dois entrarem na Gerência e um sair A4 ; ninguém mais entrar | E7: Nada, ainda
A8: 7h58:05–7h59:39 (a janela) | B8: Caixa Veterano | C8: Mesa de Recebimento A5b | D8: O silêncio da Eclusa antes da travessia | E8: Atraso
A9: 7h58:05–7h59:39 (a janela) | B9: Subgerente | C9: Na Gerência e na passagem A5 | D9: — | E9: —
A10: 7h58:05–7h59:39 (a janela) | B10: Estagiária | C10: Guichês | D10: Quem chega e não chega à Mesa | E10: Que o malote estava demorando
A11: 7h58:05–7h59:39 (a janela) | B11: Operadora | C11: Central (a câmera interna a mostra no console) | D11: A câmera 3 cair e voltar; a tampa do cesto no microfone | E11: Falha técnica
A12: 7h58:05–7h59:39 (a janela) | B12: Segurança Interno | C12: Porta Lateral | D12: Um homem de capa com um motoboy, de costas | E12: Sem tentativa
A13: 7h58:05–7h59:39 (a janela) | B13: Técnico | C13: Rua de trás | D13: O motoboy, a caixa, a batida no vidro | E13: Que precisava esconder a caixa
A14: 7h58:05–7h59:39 (a janela) | B14: Funcionário da Limpeza | C14: Saguão, com o balde | D14: Nada no corredor | E14: —
A15: 7h58:05–7h59:39 (a janela) | B15: Caixa Novato | C15: Banheiro | D15: A parede raspar duas vezes | E15: Que estava enlouquecendo
... A20: 7h58:05–7h59:39 (a janela) | B20: Monitor Remoto (oculto) | C20: Central regional | D20: A câmera 3 cair; o sensor da porta lateral já registrara 6h36 e 7h06 | E20: Que alguém abrira antes
A21: 8h01 e 8h02, o saco | B21: (vários) | D21: O Funcionário da Limpeza tira o saco do cesto, ouve passos e o larga no chão. O Caixa Novato sai do banheiro, entra no corredor procurando um lugar quieto, vê a Limpeza afastar-se do Arquivo para o fundo e abre a porta: conclui roubo. A Cliente do Cofre reconhece o vinco. O Caixa Veterano pensa no conteúdo. A Auditora separa objeto, declaração e prova. O impostor compreende que o descarte virou cena.
A22: 8h31, o cabo | B22: (vários) | D22: O Gerente entra atrás da divisória; ninguém o acompanha. O oculto vê a câmera 1 e, às 8h35, reimprime a etiqueta. O Técnico está na Central, sob os olhos de todos.

Sheet Lugares
A1: id | B1: Lugar | C1: O que tem / o que importa
A2: porta-giratoria | B2: Porta Giratória | C2: Entrada; o Gerente a trava às 8h03 e destrava às 11h12
A3: saguao | B3: Saguão | C3: Granito que guarda pegadas; cheiro de papel, lã molhada e café
A4: guiches | B4: Guichês | C4: Três, em linha de vidro, à direita
A5: mesa-recebimento | B5: Mesa de Recebimento | C5: Atrás dos Guichês, a 12 passos da porta, de frente para a Eclusa
A6: sala-gerencia | B6: Sala da Gerência | C6: Atrás da divisória fosca; impressora térmica + estabilizador (3 rápidos, 1 lento), carregador do rádio reserva, terminal compartilhado, telefone; painel atrás do armário de aço
A7: banheiro-funcionarios | B7: Banheiro dos Funcionários | C7: Parede comum com a Gerência; tranca; sem câmera; ouve-se o painel raspar
A8: porta-lateral | B8: Porta Lateral | C8: Rua de trás; chave por fora, barra por dentro; sem câmera; sensor só na central regional; na chuva a lingueta não trava
A9: corredor-restrito | B9: Corredor Restrito | C9: 24 passos; porta de aço (crachá e chave); ladrilho oco diante da Central
A10: central-monitoramento | B10: Central de Monitoramento | C10: 16 quadros; câmera interna; microfone ambiente que capta o corredor
A11: arquivo-morto | B11: Arquivo Morto | C11: Caixas por ano (a de 1998 na prateleira baixa), sacos reserva, armário de espelhos (17-B), cesto com tampa metálica, canto de infiltração
A12: nicho-rack | B12: Nicho do Rack | C12: Fora da visão da câmera 3; poeira atrás do armário
... A20: farmacia | B20: Farmácia de plantão | C20: Esquina; vitrine reflete a Vaga Blindada (fora da agência)

Sheet Rotas e visão
A1: De | B1: Até | C1: Tempo | D1: Nota
A2: Mesa de Recebimento | B2: porta do Corredor Restrito | C2: 8 s
A3: porta do Corredor | B3: Arquivo Morto | C3: 10 s | D3: Da Mesa ao Arquivo: 26 s sem pressa, 18 correndo
A4: Arquivo Morto | B4: Nicho do Rack | C4: 4 s
A5: Nicho do Rack | B5: Antecâmara | C5: 2 s | D5: Arquivo → Antecâmara: 6 s
A6: Sala da Gerência | B6: interior do Rack (pela passagem) | C6: 15 s | D6: Sem câmera
A7: Porta Giratória | B7: Sala da Gerência | C7: 6 s
A8: Antecâmara | B8: porta do Corredor (correndo) | C8: 12 s
A9: Saguão | B9: Porta Lateral | C9: 8 s
A10: Vaga Blindada | B10: Mesa | C10: 42 s | D10: Duas pausas da Eclusa
A11: Sala da Gerência | B11: Cofre (pelo Saguão e corredor) | C11: 34 s
A12: Troca completa pelo corredor | B12: — | C12: ~98 s | D12: NÃO cabe na janela de 87 s
A13: Troca pela passagem (exposição à câmera 3) | B13: 7h58:25–7h59:34 | C13: 69 s | D13: Cabe
A15: Linhas de visão e de som
A16: Posto / sensor | B16: Vê ou ouve | C16: Não vê / limite
A17: Câmera 3 | B17: Vê a entrada do Corredor, a porta da Central e metade da porta do Arquivo | C17: Não vê o Nicho do Rack nem a curva da Antecâmara
A18: Câmera 2 | B18: Vê os Guichês e a Mesa | C18: Não caiu em momento algum
A19: Câmera 1 | B19: Vê o Saguão e a divisória da Gerência (quem entra e sai) | C19: Não vê o interior da sala
A20: Câmera interna da Central | B20: Vê o console | C20: —
A21: Microfone da Central | B21: Capta o corredor (tampa do cesto às 7h59:24; estalo às 7h58:12) | C21: —
A22: Saguão (ouvido) | B22: Campainha da Eclusa, baque do Cofre, gemido da impressora atrás da divisória | C22: Não ouve conversa baixa no Arquivo
A23: Banheiro (ouvido) | B23: O painel da passagem raspar | C23: —
A24: Eclusa (visão) | B24: A Mesa, pelo vidro | C24: —
A25: Câmera da porta de serviço da padaria | B25: A Porta Lateral da agência e a rua de trás | C25: Nunca rostos sob guarda-chuva
A26: Sistema de câmeras antes das 7h30 | B26: Modo economia: só grava movimento na Porta Giratória e no Cofre | C26: —

Sheet Acessos
A1: Acesso | B1: Quem tem
A2: Porta Lateral (chave mecânica) | B2: Gerente, Subgerente, Caixa Veterano, Funcionário da Limpeza, Técnico
A3: Chave 17-B (Rack e armário de espelhos) | B3: Original com a Limpeza (emprestada ao Subgerente 7h35–7h47); cópia da Estagiária na pasta azul; a do Técnico no molho
A4: Cofre | B4: Duas chaves e duas pessoas; dupla de abertura: Subgerente e Caixa Veterano
A5: Faixa administrativa (cartão de proximidade) | B5: Gerente, Subgerente, Caixa Veterano (tesoureiro), Técnico (manutenção); 2 últimos dígitos corrompidos no pareamento
A6: Conta admin.local | B6: Criada pelo Técnico; senha ditada numa pane diante do Gerente, Subgerente, Caixa Veterano e Estagiária (que a anotou)
A7: Passagem de Serviço | B7: "Conhecimento exclusivo das três chaves da tesouraria" (planta 1987, manual 1990); o Técnico a descobriu sozinho
A8: Sensor da Porta Lateral, no dia | B8: 6h36 chave (impostor entra); 7h06 barra (sai); 7h40 chave (Técnico); 7h55 barra (Técnico sai); 7h55–7h59:51 "não travada"; 7h59:51 fechada

Sheet Capítulos
A1: Cap. | B1: Título | C1: Momento / arco | D1: Degrau da escada | E1: Grande questão | F1: Peça para o mistério maior | G1: Pergunta principal (varia) | H1: Perguntas secundárias | I1: Âncoras de hora | J1: Peça central | K1: Gancho de abertura | L1: Revelação que abre duas | M1: Subtrama que avança | N1: Efeito teia | O1: Pista genuína e falsa pista | P1: Obstáculo | Q1: Curiosidade (5DC) | R1: Pontos de ajuste | S1: Virada
A2: 0 | B2: Duas manhãs antes da mesma porta | C2: 6h28–8h03 | D2: 1 | E2: Os dois começos (quem chega × quem já estava) se encontram às 7h50 na campainha da Eclusa | S2: —
A3: 1 | B3: O malote murcho | C3: 8h02 a 8h10. Arco: o encontro e a primeira anomalia | D3: 1 | E3: O saco do Arquivo Morto é o malote que atravessou a Eclusa? | F3: Invólucro, lacre e conteúdo seguiram caminhos distintos: ML-8842 ficou, ML-8847 partiu | G3: Quem tinha acesso ao Corredor Restrito e ao Arquivo Morto naquela manhã? A lista de chaves e crachás muda de peso conforme o impostor sorteado | H3: Quando o saco foi deixado no Arquivo? Por que o malote entregue tinha outro lacre? | I3: 8h05 (câmera sem sinal), 8h07 (ML-8847 confirmado), 8h10 (a mensagem) | J3: O malote murcho | K3: O saco vazio que parece respirar | L3: O malote entregue tinha ML-8847. Quem trocou? Por que largou o antigo no caminho? | M3: A Limpeza mente sobre a chave; a Cliente quer sair antes de abrirem a pasta | N3: O piso limpo às 7h46 transforma a chave 17-B de detalhe em suspeita | O3: Genuína: a ilha seca sob o saco e a tampa torta do cesto. Falsa: a pasta do Novato com chave e senha | P3: O isolamento e o Gerente impedindo o Técnico de examinar o circuito; o perigo na rua para o carro-forte retido | Q3: Exploração: o malote e o fragmento térmico. Privação: qual saco atravessou. Estresse: o isolamento e o carro retido. Social: a mentira da Limpeza, a pressa da Cliente. Emoção: a mensagem sem origem | R3: Nenhum
A4: 2 | B4: A voz a mais | C4: 8h12 a 8h35. Arco: alguém que não deveria estar | D4: 1 | E4: De onde veio a ordem que tirou o Segurança Interno da Antecâmara? | F4: A ordem falsa partiu de dentro, da Sala da Gerência, autenticada por um cartão da faixa administrativa | G4: De quem é o cartão que pareou o rádio? Nesta altura, quatro pessoas cabem na faixa; a resposta, que fecha no Cap. 7, é a do impostor sorteado | H4: Por que o Segurança Interno obedeceu? Quem estava na agência às 6h52? | I4: 8h18 (a gravação), 8h29 (o registro da base), 8h35 (a impressora) | J4: O rádio reserva | K4: Uma gravação com a voz de um homem que ninguém reconhece | L4: A ordem saiu da Gerência. Quem estava lá às 7h58? Quem estava na agência às 6h52, antes de qualquer crachá? | M4: A Operadora entrega o bloco e a frase omitida; a Farmacêutica cala o que reconhece | N4: A frase “não cai só você” passa a pesar sobre o Gerente e o Subgerente | O4: Genuína: o pulsar do estabilizador e o horário dos crachás. Falsa: a lasca lilás no botão | P4: O Gerente transforma a falha do Segurança Interno em acusação; a Cliente recusa abrir a pasta | Q4: Exploração: o rádio e o espectro. Privação: de quem é o cartão. Estresse: o perigo na rua continua. Social: a frase omitida e as duas respostas. Emoção: a impressora que imprime sozinha | R4: A3 (a mão com fita microporosa)
A5: 3 | B5: O papel que nasceu quente | C5: 8h35 a 8h50. Arco: o objeto. Fecha com a primeira grande virada | D5: 2 (virada no fim) | E5: Por que a etiqueta nova existia antes de a câmera cair? | F5: A troca foi preparada às 6h58, não improvisada; e o malote entregue pesava o que a guia declara | G5: Quem conhecia a senha admin.local? Cinco pessoas a ouviram; a resposta só se estreita com a passagem e a escala de fechamento | H5: De onde veio a reimpressão das 8h35? O que é o arquivo ajuste_96? | I5: 8h38 (a fila), 8h44 (o carro na esquina), 8h48 (o peso) | J5: A impressora térmica de etiquetas | K5: A etiqueta no chão “como uma resposta oferecida por uma máquina que ninguém interrogara” | L5: O malote entregue pesava o que devia: nada saiu. Por que alguém trocaria um malote sem levar nada? E o que estava escrito na página que acompanhou a etiqueta? | M5: A Estagiária confessa a senha anotada; o Técnico tem a maleta revistada | N5: O peso desmonta a leitura de roubo que o grito das 8h02 tinha imposto ao saco, à pasta do Novato e à câmera | O5: Genuína: a tarefa criada às 6h58 e o “96.000” fantasma. Falsa: o roteador e os adaptadores da maleta | P5: Duas ordens incompatíveis para o Motorista; a revista humilhante da maleta | Q5: Exploração: a impressora e o verso da etiqueta. Privação: o que é ajuste_96. Estresse: as duas ordens para o Motorista. Social: a revista da maleta. Emoção: o peso que derruba o roubo | R5: Nenhum | S5: O caso parecia roubo durante a janela. A balança e a mão do Transportador mostram que o malote saiu completo. O que cai é a leitura de subtração
A6: 4 | B6: Vinte e seis segundos | C6: 8h51 a 9h25. Arco: o espaço | D6: 3 | E6: Por onde alguém faria a troca dentro de oitenta e sete segundos? | F6: Pelo corredor, a troca não cabe; pela Passagem de Serviço, entre a Gerência e o Rack, cabe | G6: Quem conhecia a passagem? Nesta altura, só o Técnico admite; a resposta completa (as três chaves da tesouraria) chega no Cap. 7 | H6: Quem queimou o cabo durante o isolamento? Onde o dinheiro poderia ter esperado? | I6: 8h51 (o curto), 9h05 (a simulação), 9h25 (a base abre o malote) | J6: O mapa físico da agência, medido pelo corpo | K6: O terminal morre no instante em que ajuste_96 vai abrir | L6: A passagem existe. Quem mais a conhece? Quem saiu da Gerência para o Rack sem atravessar o Saguão? | M6: A Limpeza confessa o empréstimo da chave; a Farmacêutica confessa o calmante | N6: A passagem muda o peso da origem da ordem falsa (Gerência) e da resposta do Técnico (“no Rack”) | O6: Genuína: as pegadas que terminam no fundo do Rack; o raspar ouvido no banheiro. Falsa: a farinha no guarda-chuva da Auditora | P6: O Gerente quer revistar todos; o Novato precisa confessar a crise e o banheiro | Q6: Exploração: o corredor medido pelo corpo e a parede que abre. Privação: quem conhece a passagem. Estresse: o cabo queimado com todos trancados. Social: as declarações lado a lado. Emoção: a lanterna rente ao chão | R6: A5 (onde cada candidato declarou estar; aqui só se registram as declarações, sem confirmação)
A7: 5 | B7: Oitenta e sete segundos | C7: 9h25 a 9h58. Arco: a janela crítica | D7: 3 | E7: Durante os oitenta e sete segundos, dinheiro saiu ou entrou? | F7: O Cofre tinha R$ 96.000 que só existiam no sistema; o malote da véspera pode ter saído curto, e alguém pode ter completado a diferença na janela | G7: Quem tinha chave da porta lateral e esteve na agência às 6h36? Cinco chaves; a resposta só se fecha no Cap. 7 | H7: Onde o dinheiro esperou? O que causou a duplicidade? | I7: 9h31 (a contagem), 9h43 (as fotografias), 9h56 (o suprimento) | J7: O peso e a contagem do malote 41 | K7: “Quatrocentos e oitenta mil. Todas verdadeiras.” | L7: Havia R$ 96.000 sem corpo no Cofre. De onde vieram os R$ 96.000 que completaram o malote? Quem entrou às 6h36? | M7: O Técnico admite a atualização; a Limpeza encontra a cinta na caixa | N7: A duplicidade dá sentido ao “96.000” do Cap. 3 e à frase do oculto no Cap. 1 | O7: Genuína: o sensor da porta lateral e a cinta rasgada. Falsa: a atualização do Técnico como prova de autoria | P7: O Gerente quer encerrar o caso no Técnico; a Auditora resiste a acusar antes da prova | Q7: Exploração: a caixa de 1998 e a cinta. Privação: de onde vieram os R$ 96.000. Estresse: o caso que se fecha rápido demais no Técnico. Social: a confissão do Novato sobre os vinte reais. Emoção: a janela ouvida pelo som | R7: Nenhum
A8: 6 | B8: O número sem corpo | C8: 9h58 a 10h25. Arco: o documento. Fecha com a segunda grande virada | D8: 3 (virada no fim) | E8: Como nasceu o número sem corpo, e quem tinha razões para escondê-lo? | F8: A duplicidade foi uma corrente de quatro falhas (saída, trava, reprocessamento, assinatura sem contagem), e o arquivo ajuste_96 é a reconstrução privada dessa noite feita por quem pretendia cobri-la | G8: Quem, entre os que falharam naquela noite, percebeu a diferença depois? A resposta é a do impostor sorteado (A1) e só aparece no Cap. 8 | H8: Por que o saco estava no chão e não no cesto? Onde o Técnico estava de fato? | I8: 10h04 (o arquivo recuperado), 10h12 (a imagem das 8h01), 10h21 (as fotografias) | J8: O arquivo ajuste_96 | K8: Um arquivo que existe porque alguém precisou escrever a noite para conseguir corrigi-la | L8: O Técnico estava lá fora na janela. Quem mais passa da Gerência ao Rack? Quem queimou o cabo às 8h31, se o Técnico estava sob vigilância? | M8: O Gerente revela a saída; a Limpeza confessa o saco; o Técnico confessa a peça sem nota | N8: A frase “não cai só você” deixa de ligar o Subgerente ao malote e passa a revelar a crise do Gerente | O8: Genuína: a luva rasgada com sangue. Falsa: a fita isolante do Técnico | P8: A Auditora diante do próprio trauma: registrar tudo e destruir inocentes, ou filtrar e repetir a omissão | Q8: Exploração: o arquivo ajuste_96 e o cesto. Privação: onde estava o Técnico. Estresse: a Auditora diante do próprio trauma. Social: cada falha da noite com o seu dono. Emoção: a capa pingando ao lado da porta | R8: Nenhum | S8: O caso parecia ser do Técnico: conta, chave, passagem, motivo, “no Rack”. As fotografias do Padeiro o põem do lado de fora. O que cai é a leitura que o colocava na rota
A9: 7 | B9: Quinze versões para um fato | C9: 10h25 a 10h50. Arco: o confronto das versões | D9: 4 | E9: Quais versões pertencem ao ato e quais protegem só vergonhas particulares? | F9: Só as três chaves da tesouraria conheciam a passagem; as versões convergem sobre uma delas, mas a autoria ainda admite disputa até o Cap. 8 | G9: Qual das três chaves da tesouraria não estava onde disse? É o ponto A5 | H9: Quem queimou o cabo? Quem assinou o malote da véspera sem contar? | I9: 10h28 (o quadro), 10h41 (a regional responde), 10h46 (o checksum) | J9: O quadro das quinze funções | K9: A Auditora escreve funções no quadro e se recusa a escrever nomes | L9: O cabo foi o Gerente. Ele também esteve no malote? E quem vê a agência de longe e reimprimiu a etiqueta? | M9: Gerente, Cliente, Farmacêutica e Veterano entregam o que escondiam | N9: A planta da Cliente converte a passagem de indício do Técnico em privilégio da tesouraria | O9: Genuína: o checksum e o titular do saque. Falsa, desfeita: a farinha da Auditora | P9: O Gerente tenta conservar uma versão útil; a Cliente precisa expor o pai | Q9: Exploração: a planta de 1987 e as câmeras. Privação: qual das três chaves. Estresse: a resposta da regional. Social: o confronto das versões. Emoção: a fita estreita contra a larga | R9: A2, A3, A4, A5, A5b, A6, A7, A8
A10: 8 | B10: A soma impossível | C10: 10h52–11h12; epílogo na manhã seguinte, 8h10 | D10: 5 e 6 (epílogo) | E10: Função. Retomar as sete grandes questões; a acusação de todos; a revelação em seis movimentos, escrita em uma variante por candidato; o epílogo na manhã seguinte, com a última mensagem do oculto; a pergunta de valor. O texto público abaixo é a variante de referência (impostor: o Subgerente). As variantes G (Gerente) e V (Caixa Veterano) estão depois do quadro. As sete grandes questões e as respostas. 1. O saco do Arquivo era o malote da véspera, esvaziado na troca e largado no chão pela Limpeza. 2. A voz saiu da Gerência, pelo rádio pareado com o cartão do impostor. 3. A etiqueta foi preparada às 6h58, antes da janela. 4. A rota foi a passagem entre a Gerência e o Rack. 5. Nos 87 segundos, o dinheiro entrou. 6. O número sem corpo nasceu de quatro falhas, onze dias antes. 7. As outras versões protegiam vergonhas reais e periféricas. | S10: —

Sheet Seis eixos
A1: Id | B1: Cap. | C1: Eixo | D1: Fato | E1: Fixo ou varia | F1: Degrau
A2: E1-1 | B2: 1 | C2: Há quanto tempo | D2: Arquivo limpo às 7h46; travessia às 8h00; achado às 8h02; confirmação às 8h07 | E2: Fixo | F2: 1
A3: E1-2 | B3: 1 | C3: Onde | D3: Arquivo Morto, Mesa de Recebimento, Eclusa | E3: Fixo | F3: 1
A4: E1-3 | B4: 1 | C4: Como | D4: Troca de invólucro e de lacre numa janela sem imagem | E4: Fixo | F4: 1
A5: E1-4 | B5: 1 | C5: Quem | D5: Quem tinha crachá do corredor, chave 17-B ou acesso à Mesa | E5: Fixo | F5: 1
A6: E1-5 | B6: 1 | C6: Qual e que tipo | D6: Um invólucro vazio, um lacre rompido, um fragmento térmico; violação de procedimento, sem prova de subtração | E6: Fixo | F6: 1
A7: E1-6 | B7: 1 | C7: Perspectiva | D7: Novato: roubo. Cliente: é o mesmo saco. Auditora: invólucro não é conteúdo. Limpeza: o saco veio depois das 7h46 (e se cala sobre a chave). Motorista: a via diz ML-8842; Segurança do Veículo: conferiu a tela. Operadora: ninguém entrou no Arquivo entre 7h46 e 7h58. Gerente: subtração | E7: Fixo | F7: 1
A8: E2-1 | B8: 2 | C8: Há quanto tempo | D8: Pareamento às 7h57:55; ordem às 7h58:05; antecipação às 6h52; primeiro crachá do dia às 7h10 | E8: Fixo | F8: 1
A9: E2-2 | B9: 2 | C9: Onde | D9: Sala da Gerência (estabilizador), Porta Lateral, Central | E9: Fixo | F9: 1
A10: E2-3 | B10: 2 | C10: Como | D10: Rádio pareado por cartão de proximidade e código verbal correto | E10: Fixo | F10: 1
A11: E2-4 | B11: 2 | C11: Quem | D11: Os quatro da faixa administrativa: Gerente, Subgerente, Caixa Veterano, Técnico | E11: Varia (A3 (a mão com fita microporosa)) | F11: 1
A12: E2-5 | B12: 2 | C12: Qual e que tipo | D12: Voz comprimida, pulsar do estabilizador, lasca de esmalte, registro com dígitos corrompidos | E12: Fixo | F12: 1
A13: E2-6 | B13: 2 | C13: Perspectiva | D13: Segurança Interno: viu pelo vidro um homem de capa com um motoboy. Estagiária: reconhece o estabilizador. Operadora: o esmalte é dela, de ontem. Farmacêutica: duas mãos com fita. Operador de Rádio: a chamada saiu da Gerência | E13: Varia (A3 (a mão com fita microporosa)) | F13: 1
A14: E3-1 | B14: 3 | C14: Há quanto tempo | D14: Tarefa criada às 6h58; executada às 7h53; reimpressão às 8h35; registro de peso às 8h00 | E14: Fixo | F14: 2 (virada no fim)
A15: E3-2 | B15: 3 | C15: Onde | D15: Sala da Gerência (terminal e impressora), Rack, Eclusa | E15: Fixo | F15: 2 (virada no fim)
A16: E3-3 | B16: 3 | C16: Como | D16: Conta de manutenção, tarefa agendada, edição do registro da remessa; reimpressão por acesso remoto | E16: Fixo | F16: 2 (virada no fim)
A17: E3-4 | B17: 3 | C17: Quem | D17: Quem ouviu a senha numa pane: Gerente, Subgerente, Caixa Veterano, Técnico, Estagiária | E17: Fixo | F17: 2 (virada no fim)
A18: E3-5 | B18: 3 | C18: Qual e que tipo | D18: Etiqueta legítima usada fora do rito; impressão fantasma “96.000”; peso de 7,0 kg | E18: Fixo | F18: 2 (virada no fim)
A19: E3-6 | B19: 3 | C19: Perspectiva | D19: Operadora: a fila prova preparo. Técnico: a conta é dele, o conector foi preparado. Caixa Veterano: lembra uma reimpressão de onze dias antes. Transportador: o peso é o declarado. Gerente: papel no lugar de dinheiro | E19: Fixo | F19: 2 (virada no fim)
A20: E4-1 | B20: 4 | C20: Há quanto tempo | D20: Janela de 7h58:12 a 7h59:39; curto às 8h51; simulação às 9h05 | E20: Fixo | F20: 3
A21: E4-2 | B21: 4 | C21: Onde | D21: Rack Técnico, Arquivo Morto, Nicho do Rack, Banheiro, Passagem de Serviço | E21: Fixo | F21: 3
A22: E4-3 | B22: 4 | C22: Como | D22: Rota cronometrada; pegadas na umidade; painel removível | E22: Fixo | F22: 3
A23: E4-4 | B23: 4 | C23: Quem | D23: Quem declarou estar perto do Rack; quem ouviu a parede | E23: Varia (A5 (onde cada candidato declarou estar; aqui só se registram as declarações, sem confirmação)) | F23: 3
A24: E4-5 | B24: 4 | C24: Qual e que tipo | D24: Pegadas em meia-lua, cabo derretido, o raspar da parede; indícios de oportunidade, não de autoria | E24: Fixo | F24: 3
A25: E4-6 | B25: 4 | C25: Perspectiva | D25: Técnico: diz que estava no Rack, a pior resposta possível. Novato: ouviu a parede raspar duas vezes. Limpeza: o canto úmido guarda pegadas. Gerente: “minha sala não é minha culpa”. Padeiro: a figura das 6h28 | E25: Varia (A5 (onde cada candidato declarou estar; aqui só se registram as declarações, sem confirmação)) | F25: 3
A26: E5-1 | B26: 5 | C26: Há quanto tempo | D26: Contagem da base às 9h31; duplicidade de onze dias antes (18h54 e 19h11); porta lateral às 6h36 e 7h06 | E26: Fixo | F26: 3
A27: E5-2 | B27: 5 | C27: Onde | D27: Base, Arquivo Morto (caixa de 1998), Porta Lateral, rua de trás | E27: Fixo | F27: 3
A28: E5-3 | B28: 5 | C28: Como | D28: Reconstrução da janela pelo som; sensor da porta; caixa de arquivo como esconderijo | E28: Fixo | F28: 3
A29: E5-4 | B29: 5 | C29: Quem | D29: Quem tem chave da porta lateral: Gerente, Subgerente, Caixa Veterano, Limpeza, Técnico | E29: Fixo | F29: 3
A30: E5-5 | B30: 5 | C30: Qual e que tipo | D30: Cédulas verdadeiras e completas; R$ 96.000 sem lastro; cinta de maço rasgada | E30: Fixo | F30: 3
A31: E5-6 | B31: 5 | C31: Perspectiva | D31: Caixa Novato: “e se alguém colocou?”. Caixa Veterano: o recibo é um só. Operadora: a tampa do cesto às 7h59:24 e o sensor da porta. Caixa Veterano: a caixa de 1998. Novato: os raspados batem com os horários. Técnico: admite a atualização de onze dias antes. Gerente: tudo aponta o Técnico | E31: Fixo | F31: 3
