Workbook

Sheet Leia-me
A1: O Impostor · Matriz de falas por personalidade
A3: O que é | B3: Cada linha é uma fala de personagem (ou da voz, ou do Faroleiro). As 6 colunas de tipo dizem a MESMA informação; só muda a forma de escrever. O tipo de cada personagem é sorteado pela semente da partida e nunca aparece para o jogador.
A4: Abas | B4: Cap 1 a Final: tronco comum (falas que se repetem em toda partida). Partidas Cap 1-2 a Partidas Cap 6: falas próprias de cada partida (coluna Partida). Resumo: contagem. Dúvidas: o que precisa de decisão sua. Pendentes: o que a etapa 1 listou para a etapa 2.
A5: Onde editar | B5: Só as 6 colunas de tipo (fundo creme) e, se precisar, os Itens. Não mexa em ID nem em Fala original.
A6: Itens | B6: Palavras que carregam a informação (nas falas de partida, são as pistas: segundos, clarões, lugares, cores). Precisam aparecer em todas as 6 versões. A coluna Faltam conta quantos itens sumiram nas 6 versões (ignora maiúscula, mas não acento) e fica vermelha se for maior que zero.
A7: Fichas | B7: {Inv}/{inv} = O/o Investigador (ou "você", se for o personagem do jogador); {de:pol} = do Policial; {a:pol} = ao Policial. Aliases: inv, her, res, jor, pol, obs, tab, gov, adv, jar, che, ele, med (o Médico, 13º personagem, só com 12 humanos).
A8: Grosseria | B8: Nível médio: ofensa ao personagem sim, palavrão não (decisão do Mario, 02/10/2026).
A9: Evasivo | B9: As digressões usam só assunto neutro (chuva, frio, umidade, cansaço, estrada, demora). Nunca vento: o cânone diz que a chuva cai reta, sem vento.
A11: Tipo | B11: Reatividade | C11: Confiança | D11: Filtro | E11: Lealdade | F11: Esfriamento | G11: Como escreve
A12: Explosivo | B12: 0.9 | C12: 0.3 | D12: 0.1 | E12: 0.2 | F12: 0.5 | G12: Exclamações, acusa pelo tom, impaciente; ofende sem palavrão.
A13: Calmo opaco | B13: 0.2 | C13: 0.2 | D13: 0.8 | E13: 0.3 | F13: 0.85 | G13: Voz baixa, frases curtas e partidas; diz tudo, aos pedaços.
A14: Ingênuo | B14: 0.4 | C14: 0.9 | D14: 0.1 | E14: 0.2 | F14: 0.8 | G14: Hesita, pede confirmação, acredita; nas pistas, sem "acho que" antes do fato.
A15: Leal cego | B15: 0.5 | C15: 0.4 | D15: 0.6 | E15: 0.95 | F15: 0.7 | G15: Fala em defesa de alguém; padrão: lealdade a ele (o proprietário) ou à casa.
A16: Evasivo | B16: 0.3 | C16: 0.3 | D16: 0.9 | E16: 0.2 | F16: 0.75 | G16: Rodeia com assunto neutro e solta a informação no meio.
A17: Burocrata | B17: 0.2 | C17: 0.2 | D17: 0.7 | E17: 0.1 | F17: 0.9 | G17: Formato de registro: consta, registre, itens em sequência.

Sheet Resumo
A1: Aba | B1: Falas | C1: Células (falas × 6) | D1: Linhas com item faltando
A2: Cap 1 | B2: =COUNTA('Cap 1'!A2:A49) | C2: =B2*6 | D2: =COUNTIF('Cap 1'!X2:X49,">0")
A3: Cap 2 | B3: =COUNTA('Cap 2'!A2:A43) | C3: =B3*6 | D3: =COUNTIF('Cap 2'!X2:X43,">0")
A4: Cap 3 | B4: =COUNTA('Cap 3'!A2:A32) | C4: =B4*6 | D4: =COUNTIF('Cap 3'!X2:X32,">0")
A5: Cap 4 | B5: =COUNTA('Cap 4'!A2:A28) | C5: =B5*6 | D5: =COUNTIF('Cap 4'!X2:X28,">0")
A6: Cap 5 | B6: =COUNTA('Cap 5'!A2:A18) | C6: =B6*6 | D6: =COUNTIF('Cap 5'!X2:X18,">0")
A7: Cap 6 | B7: =COUNTA('Cap 6'!A2:A26) | C7: =B7*6 | D7: =COUNTIF('Cap 6'!X2:X26,">0")
A8: Final | B8: =COUNTA(Final!A2:A5) | C8: =B8*6 | D8: =COUNTIF(Final!X2:X5,">0")
A9: Partidas Cap 1-2 | B9: =COUNTA('Partidas Cap 1-2'!A2:A55) | C9: =B9*6 | D9: =COUNTIF('Partidas Cap 1-2'!Y2:Y55,">0")
A10: Partidas Cap 3-4 | B10: =COUNTA('Partidas Cap 3-4'!A2:A90) | C10: =B10*6 | D10: =COUNTIF('Partidas Cap 3-4'!Y2:Y90,">0")
A11: Partidas Cap 5 | B11: =COUNTA('Partidas Cap 5'!A2:A39) | C11: =B11*6 | D11: =COUNTIF('Partidas Cap 5'!Y2:Y39,">0")
A12: Partidas Cap 6 | B12: =COUNTA('Partidas Cap 6'!A2:A131) | C12: =B12*6 | D12: =COUNTIF('Partidas Cap 6'!Y2:Y131,">0")
A13: Total | B13: =SUM(B2:B12) | C13: =SUM(C2:C12) | D13: =SUM(D2:D12)

Sheet Dúvidas
A1: Tema | B1: Dúvida ou decisão
A2: Resolvido 02/10 | B2: Passada 2 aplicada (chamada de uma palavra, sem vento, deslizes, fin-04, voz com uma função por momento, Ingênuo sem hesitar antes do fato, Explosivo sem acusar, Leal só onde cabe, Burocrata que anota, falas curtas sem muleta).
A3: Resolvido 02/10 | B3: Deslizes de quem voltou (P2 e P10) reescritos com "terça passada" no código.
A4: Resolvido 02/10 | B4: P15: o Faroleiro diz "vulto amarelo" (o farol só vê vultos). Mudou também no Cap. 6 e no livro do farol.
A5: Resolvido 02/10 | B5: Segundos da mensagem no escuro: Leal cego +20, Ingênuo +36, Evasivo +60, Explosivo +90, Calmo opaco +100, Burocrata +106.
A6: Resolvido 02/10 | B6: Falantes deduzidos confirmados: "De despensa." (Chefe), "O senhor escreveu isso…" (Investigador), "Tem barro vermelho…" (Observadora), "Tirou o blazer no frio?" (Jornalista).
A7: Resolvido 02/10 | B7: Rádio: o Faroleiro passava na casa antes do turno (Cap. 4: o gato do Jardineiro, as terças da Governanta); o ajudante do Eletricista confirma a tomada (Cap. 6). Falas c4-25 a c4-27 e c6-24. Toda mensagem de rádio toca a estática.
A8: Cânone | B8: P13 "estava lúcido": pista falsa intencional; as seis mantêm "lúcido".
A9: Cânone | B9: "Quarto dos fundos", "quarto do fundo" e "quarto de serviço" tratados como o mesmo cômodo; na matriz o nome nunca varia entre tipos.
A10: Código | B10: Quando o narrador fala pelo personagem do jogador, usa o tipo sorteado.
A11: Código | B11: Textos por extenso que deveriam ser ficha (P2 Cap. 5 "o Policial"; P12 Cap. 6 "respondi ao Policial", "à Governanta"; Cap. 2 a Herdeira em "É o número do seu pai?"): corrigir quando a matriz entrar no jogo.
A12: Código | B12: O livro do farol usa o texto base da linha do Faroleiro, sem tipo.

Sheet Cap 1
A1: ID | B1: Cena | C1: Momento | D1: Quem fala | E1: Com quem | F1: Condição | G1: Item 1 | H1: Item 2 | I1: Item 3 | J1: Item 4 | K1: Item 5 | L1: Item 6 | M1: Item 7 | N1: Item 8 | O1: Item 9 | P1: Item 10 | Q1: Fala original | R1: Explosivo | S1: Calmo opaco | T1: Ingênuo | U1: Leal cego | V1: Evasivo | W1: Burocrata | X1: Faltam | Y1: Nota
A2: c1-01 | B2: chegada: a contagem e os lacres | C2: roteiro | D2: tabeliao | policial (cond: o Tabelião se estiver na casa) | E2: grupo (citado na narração) | G2: leitura | H2: nada sai do lugar | I2: nem vocês | Q2: Até a leitura, nada sai do lugar. Nem vocês. | R2: Nada sai do lugar até a leitura! Nem vocês, e não quero discussão. | S2: Até a leitura… nada sai do lugar. Nem vocês. | T2: Até a leitura, nada sai do lugar. Nem vocês, tá bom? | U2: Até a leitura, nada sai do lugar. Nem vocês. Sem exceção. | V2: Foi longa, a estrada até aqui… Até a leitura, nada sai do lugar. Nem vocês. | W2: Para a ata: até a leitura, nada sai do lugar. Nem vocês. | X2: =SUMPRODUCT(($G2:$P2<>"")*ISERROR(SEARCH($G2:$P2,R2)))+SUMPRODUCT(($G2:$P2<>"")*ISERROR(SEARCH($G2:$P2,S2)))+SUMPRODUCT(($G2:$P2<>"")*ISERROR(SEARCH($G2:$P2,T2)))+SUMPRODUCT(($G2:$P2<>"")*ISERROR(SEARCH($G2:$P2,U2)))+SUMPRODUCT(($G2:$P2<>"")*ISERROR(SEARCH($G2:$P2,V2)))+SUMPRODUCT(($G2:$P2<>"")*ISERROR(SEARCH($G2:$P2,W2))) | Y2: Enquadre: '{Cond} contou os convocados duas vezes e anotou N. Depois conferiu os lacres... <i>"fala"</i>'.
A3: c1-02 | B3: o rádio do farol (casa com funcionários) | C3: roteiro | D3: faroleiro | E3: grupo (rádio, citado na narração) | F3: com funcionários | G3: farol | H3: pessoal do serviço | I3: passou a noite | J3: convocados | K3: chegaram bem | Q3: Casa da Costa, aqui é o farol. O pessoal do serviço passou a noite aí, como eu aconselhei. Os convocados chegaram bem? | R3: Casa da Costa, aqui é o farol! O pessoal do serviço passou a noite aí, como eu aconselhei. E os convocados, chegaram bem ou não? | S3: Casa da Costa… aqui é o farol. O pessoal do serviço… passou a noite aí. Eu aconselhei. Os convocados… chegaram bem? | T3: Casa da Costa? Aqui é o farol. O pessoal do serviço passou a noite aí, como eu aconselhei… Os convocados chegaram bem? Tomara que sim. | U3: Casa da Costa, aqui é o farol. O pessoal do serviço passou a noite aí, como eu aconselhei. Os convocados chegaram bem? | V3: Casa da Costa, aqui é o farol. Umidade aqui em cima que não acaba… O pessoal do serviço passou a noite aí, como eu aconselhei. E os convocados, chegaram bem? | W3: Casa da Costa, aqui é o farol. Para registro: o pessoal do serviço passou a noite aí, por orientação minha. Convocados: chegaram bem? | X3: =SUMPRODUCT(($G3:$P3<>"")*ISERROR(SEARCH($G3:$P3,R3)))+SUMPRODUCT(($G3:$P3<>"")*ISERROR(SEARCH($G3:$P3,S3)))+SUMPRODUCT(($G3:$P3<>"")*ISERROR(SEARCH($G3:$P3,T3)))+SUMPRODUCT(($G3:$P3<>"")*ISERROR(SEARCH($G3:$P3,U3)))+SUMPRODUCT(($G3:$P3<>"")*ISERROR(SEARCH($G3:$P3,V3)))+SUMPRODUCT(($G3:$P3<>"")*ISERROR(SEARCH($G3:$P3,W3))) | Y3: Enquadre: 'O velho rádio VHF chia. É o farol: <i>"fala"</i>'. 'Casa da Costa' é nome da casa, não de pessoa.
A4: c1-03 | B4: da cozinha, os funcionários ouvem a chegada | C4: chat | D4: voz(FUNCIONARIOS) | E4: grupo do serviço (só funcionário humano vê) | F4: com funcionários; jogador é funcionário | G4: chegou gente | H4: muita gente | I4: pela frente | Q4: Chegou gente. Muita gente, pela frente. | R4: Chegou gente! Muita gente, pela frente. Que hora para isso. | S4: Chegou gente… Muita gente. Pela frente. | T4: Chegou gente… muita gente, pela frente. Vocês ouviram também? | U4: Chegou gente. Muita gente, pela frente. | V4: Mal se enxerga com essa chuva… Chegou gente. Muita gente, pela frente. | W4: Chegou gente. Muita gente. Acesso: pela frente. | X4: =SUMPRODUCT(($G4:$P4<>"")*ISERROR(SEARCH($G4:$P4,R4)))+SUMPRODUCT(($G4:$P4<>"")*ISERROR(SEARCH($G4:$P4,S4)))+SUMPRODUCT(($G4:$P4<>"")*ISERROR(SEARCH($G4:$P4,T4)))+SUMPRODUCT(($G4:$P4<>"")*ISERROR(SEARCH($G4:$P4,U4)))+SUMPRODUCT(($G4:$P4<>"")*ISERROR(SEARCH($G4:$P4,V4)))+SUMPRODUCT(($G4:$P4<>"")*ISERROR(SEARCH($G4:$P4,W4))) | Y4: Falante pode ser homem ou mulher: sem adjetivo de gênero sobre si.
A5: c1-04 | B5: os funcionários sabem que o farol falou deles | C5: chat | D5: voz(FUNCIONARIOS.slice().reverse()) | E5: grupo do serviço (só funcionário humano vê) | F5: com funcionários; jogador é funcionário | G5: farol | H5: falou da gente | I5: rádio | J5: cozinha | Q5: O farol falou da gente no rádio. Eles vão vir para a cozinha. | R5: O farol falou da gente no rádio! Agora eles vão vir para a cozinha, era só o que faltava. | S5: O farol… falou da gente no rádio. Eles vão vir. Para a cozinha. | T5: O farol falou da gente no rádio, vocês ouviram? Eles vão vir para a cozinha… tudo bem por vocês? | U5: O farol falou da gente no rádio. Eles vão vir para a cozinha. | V5: Que demora essa noite… O farol falou da gente no rádio. Eles vão vir para a cozinha. | W5: Anoto: o farol falou da gente no rádio. Em seguida, eles vêm para a cozinha. | X5: =SUMPRODUCT(($G5:$P5<>"")*ISERROR(SEARCH($G5:$P5,R5)))+SUMPRODUCT(($G5:$P5<>"")*ISERROR(SEARCH($G5:$P5,S5)))+SUMPRODUCT(($G5:$P5<>"")*ISERROR(SEARCH($G5:$P5,T5)))+SUMPRODUCT(($G5:$P5<>"")*ISERROR(SEARCH($G5:$P5,U5)))+SUMPRODUCT(($G5:$P5<>"")*ISERROR(SEARCH($G5:$P5,V5)))+SUMPRODUCT(($G5:$P5<>"")*ISERROR(SEARCH($G5:$P5,W5)))
A6: c1-05 | B6: o grupo reage ao rádio (com funcionários) | C6: chat | D6: residente | E6: grupo | F6: com funcionários | G6: pessoal do serviço | H6: ninguém falou | I6: funcionários | Q6: Pessoal do serviço? Ninguém falou em funcionários. | R6: Pessoal do serviço?! Ninguém falou em funcionários, que história é essa? | S6: Pessoal do serviço… Ninguém falou em funcionários. | T6: Pessoal do serviço? Ninguém falou em funcionários, falou? Desculpa, posso ter perdido. | U6: Pessoal do serviço? Ninguém falou em funcionários. | V6: Pessoal do serviço? Depois de tanta estrada, a gente ouve cada coisa… Ninguém falou em funcionários. | W6: Pessoal do serviço? Ponto não previsto: ninguém falou em funcionários. | X6: =SUMPRODUCT(($G6:$P6<>"")*ISERROR(SEARCH($G6:$P6,R6)))+SUMPRODUCT(($G6:$P6<>"")*ISERROR(SEARCH($G6:$P6,S6)))+SUMPRODUCT(($G6:$P6<>"")*ISERROR(SEARCH($G6:$P6,T6)))+SUMPRODUCT(($G6:$P6<>"")*ISERROR(SEARCH($G6:$P6,U6)))+SUMPRODUCT(($G6:$P6<>"")*ISERROR(SEARCH($G6:$P6,V6)))+SUMPRODUCT(($G6:$P6<>"")*ISERROR(SEARCH($G6:$P6,W6)))
A7: c1-06 | B7: o grupo reage ao rádio (com funcionários) | C7: chat | D7: jornalista | E7: grupo | F7: com funcionários | G7: quem | H7: cozinha | Q7: Quem está na cozinha? | R7: Quem está na cozinha?! | S7: Quem… está na cozinha? | T7: Quem está na cozinha…? | U7: Quem está na cozinha? | V7: Hum… quem está na cozinha? | W7: Quem está na cozinha? | X7: =SUMPRODUCT(($G7:$P7<>"")*ISERROR(SEARCH($G7:$P7,R7)))+SUMPRODUCT(($G7:$P7<>"")*ISERROR(SEARCH($G7:$P7,S7)))+SUMPRODUCT(($G7:$P7<>"")*ISERROR(SEARCH($G7:$P7,T7)))+SUMPRODUCT(($G7:$P7<>"")*ISERROR(SEARCH($G7:$P7,U7)))+SUMPRODUCT(($G7:$P7<>"")*ISERROR(SEARCH($G7:$P7,V7)))+SUMPRODUCT(($G7:$P7<>"")*ISERROR(SEARCH($G7:$P7,W7)))
A8: c1-07 | B8: o Tabelião põe os funcionários no grupo | C8: roteiro | D8: tabeliao | E8: grupo (citado na narração) | F8: com funcionários | G8: ata | H8: todos | I8: na casa | Q8: Para a ata, todos que estão na casa. | R8: Para a ata, todos que estão na casa! Sem deixar ninguém de fora. | S8: Para a ata… todos que estão na casa. | T8: É para a ata… todos que estão na casa, certo? Ninguém fica chateado, espero. | U8: Para a ata, todos que estão na casa. Todos. | V8: Com tanta demora, melhor adiantar… Para a ata, todos que estão na casa. | W8: Para a ata: todos que estão na casa, um a um. | X8: =SUMPRODUCT(($G8:$P8<>"")*ISERROR(SEARCH($G8:$P8,R8)))+SUMPRODUCT(($G8:$P8<>"")*ISERROR(SEARCH($G8:$P8,S8)))+SUMPRODUCT(($G8:$P8<>"")*ISERROR(SEARCH($G8:$P8,T8)))+SUMPRODUCT(($G8:$P8<>"")*ISERROR(SEARCH($G8:$P8,U8)))+SUMPRODUCT(($G8:$P8<>"")*ISERROR(SEARCH($G8:$P8,V8)))+SUMPRODUCT(($G8:$P8<>"")*ISERROR(SEARCH($G8:$P8,W8))) | Y8: Enquadre: '{Tab} anotou mais N e pôs os números deles no grupo do cartório: <i>"fala"</i>'.
A9: c1-08 | B9: primeira fala do serviço no grupo | C9: chat | D9: voz(FUNCIONARIOS) = governanta | E9: grupo | F9: com funcionários; um só funcionário (casa de 8) | G9: boa noite | H9: ninguém me avisou | I9: tanta gente | Q9: Boa noite. Ninguém me avisou que vinha tanta gente. | R9: Boa noite. Ninguém me avisou que vinha tanta gente, ninguém! | S9: Boa noite. Ninguém me avisou… que vinha tanta gente. | T9: Boa noite… Ninguém me avisou que vinha tanta gente. Desculpem a surpresa. | U9: Boa noite. Ninguém me avisou que vinha tanta gente. | V9: Boa noite. Molhados da chuva, todos… Ninguém me avisou que vinha tanta gente. | W9: Boa noite. Anoto: ninguém me avisou que vinha tanta gente. | X9: =SUMPRODUCT(($G9:$P9<>"")*ISERROR(SEARCH($G9:$P9,R9)))+SUMPRODUCT(($G9:$P9<>"")*ISERROR(SEARCH($G9:$P9,S9)))+SUMPRODUCT(($G9:$P9<>"")*ISERROR(SEARCH($G9:$P9,T9)))+SUMPRODUCT(($G9:$P9<>"")*ISERROR(SEARCH($G9:$P9,U9)))+SUMPRODUCT(($G9:$P9<>"")*ISERROR(SEARCH($G9:$P9,V9)))+SUMPRODUCT(($G9:$P9<>"")*ISERROR(SEARCH($G9:$P9,W9)))
A10: c1-09 | B10: primeira fala do serviço no grupo | C10: chat | D10: voz(FUNCIONARIOS) | E10: grupo | F10: com funcionários; mais de um funcionário | G10: boa noite | H10: ninguém nos avisou | I10: tanta gente | Q10: Boa noite. Ninguém nos avisou que vinha tanta gente. | R10: Boa noite. Ninguém nos avisou que vinha tanta gente, ninguém! | S10: Boa noite. Ninguém nos avisou… que vinha tanta gente. | T10: Boa noite… Ninguém nos avisou que vinha tanta gente. Desculpem a cara de susto. | U10: Boa noite. Ninguém nos avisou que vinha tanta gente. | V10: Boa noite. Que noite úmida… Ninguém nos avisou que vinha tanta gente. | W10: Boa noite. Consta: ninguém nos avisou que vinha tanta gente. | X10: =SUMPRODUCT(($G10:$P10<>"")*ISERROR(SEARCH($G10:$P10,R10)))+SUMPRODUCT(($G10:$P10<>"")*ISERROR(SEARCH($G10:$P10,S10)))+SUMPRODUCT(($G10:$P10<>"")*ISERROR(SEARCH($G10:$P10,T10)))+SUMPRODUCT(($G10:$P10<>"")*ISERROR(SEARCH($G10:$P10,U10)))+SUMPRODUCT(($G10:$P10<>"")*ISERROR(SEARCH($G10:$P10,V10)))+SUMPRODUCT(($G10:$P10<>"")*ISERROR(SEARCH($G10:$P10,W10))) | Y10: Falante pode ser homem ou mulher.
A11: c1-10 | B11: o Policial responde ao serviço | C11: chat | D11: policial | E11: grupo | F11: com funcionários | G11: ninguém nos avisou | H11: alguém aqui | Q11: E ninguém nos avisou que tinha alguém aqui. | R11: E ninguém nos avisou que tinha alguém aqui! Bonito, hein. | S11: E ninguém nos avisou… que tinha alguém aqui. | T11: E ninguém nos avisou que tinha alguém aqui… ou fui eu que não ouvi? | U11: E ninguém nos avisou que tinha alguém aqui. | V11: A estrada, a demora, tudo atrasado… E ninguém nos avisou que tinha alguém aqui. | W11: Falha de comunicação: ninguém nos avisou que tinha alguém aqui. | X11: =SUMPRODUCT(($G11:$P11<>"")*ISERROR(SEARCH($G11:$P11,R11)))+SUMPRODUCT(($G11:$P11<>"")*ISERROR(SEARCH($G11:$P11,S11)))+SUMPRODUCT(($G11:$P11<>"")*ISERROR(SEARCH($G11:$P11,T11)))+SUMPRODUCT(($G11:$P11<>"")*ISERROR(SEARCH($G11:$P11,U11)))+SUMPRODUCT(($G11:$P11<>"")*ISERROR(SEARCH($G11:$P11,V11)))+SUMPRODUCT(($G11:$P11<>"")*ISERROR(SEARCH($G11:$P11,W11)))
A12: c1-11 | B12: o rádio do farol (casa sem funcionários) | C12: roteiro | D12: faroleiro | E12: grupo (rádio, citado na narração) | F12: sem funcionários (casa de 6) | G12: farol | H12: luz | I12: ala de serviço | J12: desde a tarde | K12: tudo bem | Q12: Casa da Costa, aqui é o farol. Vi luz na ala de serviço desde a tarde. Está tudo bem aí? | R12: Casa da Costa, aqui é o farol! Vi luz na ala de serviço desde a tarde. Está tudo bem aí ou não? | S12: Casa da Costa… aqui é o farol. Luz na ala de serviço… desde a tarde. Tudo bem aí? | T12: Casa da Costa? Aqui é o farol. Vi luz na ala de serviço desde a tarde… está tudo bem aí? Fiquei pensando. | U12: Casa da Costa, aqui é o farol. Vi luz na ala de serviço desde a tarde. Está tudo bem aí? | V12: Casa da Costa, aqui é o farol. Um frio aqui em cima que entra nos ossos… Vi luz na ala de serviço desde a tarde. Está tudo bem aí? | W12: Casa da Costa, aqui é o farol. Ocorrência: luz na ala de serviço desde a tarde. Está tudo bem aí? | X12: =SUMPRODUCT(($G12:$P12<>"")*ISERROR(SEARCH($G12:$P12,R12)))+SUMPRODUCT(($G12:$P12<>"")*ISERROR(SEARCH($G12:$P12,S12)))+SUMPRODUCT(($G12:$P12<>"")*ISERROR(SEARCH($G12:$P12,T12)))+SUMPRODUCT(($G12:$P12<>"")*ISERROR(SEARCH($G12:$P12,U12)))+SUMPRODUCT(($G12:$P12<>"")*ISERROR(SEARCH($G12:$P12,V12)))+SUMPRODUCT(($G12:$P12<>"")*ISERROR(SEARCH($G12:$P12,W12))) | Y12: Enquadre: 'O velho rádio VHF chia. É o farol: <i>"fala"</i>'.
A13: c1-12 | B13: o grupo reage ao rádio (sem funcionários) | C13: chat | D13: residente | E13: grupo | F13: sem funcionários (casa de 6) | G13: à tarde | H13: ninguém de nós | I13: ala de serviço | Q13: Chegamos à tarde, mas ninguém de nós foi até a ala de serviço. | R13: Chegamos à tarde, mas ninguém de nós foi até a ala de serviço! Ninguém. | S13: Chegamos à tarde… Ninguém de nós foi até a ala de serviço. | T13: Chegamos à tarde, mas ninguém de nós foi até a ala de serviço… não é, gente? | U13: Chegamos à tarde, mas ninguém de nós foi até a ala de serviço. | V13: A estrada estava um horror, chegamos à tarde… Mas ninguém de nós foi até a ala de serviço. | W13: Chegada: à tarde. Ninguém de nós foi até a ala de serviço. | X13: =SUMPRODUCT(($G13:$P13<>"")*ISERROR(SEARCH($G13:$P13,R13)))+SUMPRODUCT(($G13:$P13<>"")*ISERROR(SEARCH($G13:$P13,S13)))+SUMPRODUCT(($G13:$P13<>"")*ISERROR(SEARCH($G13:$P13,T13)))+SUMPRODUCT(($G13:$P13<>"")*ISERROR(SEARCH($G13:$P13,U13)))+SUMPRODUCT(($G13:$P13<>"")*ISERROR(SEARCH($G13:$P13,V13)))+SUMPRODUCT(($G13:$P13<>"")*ISERROR(SEARCH($G13:$P13,W13)))
A14: c1-13 | B14: o grupo reage ao rádio (sem funcionários) | C14: chat | D14: jornalista | E14: grupo | F14: sem funcionários (casa de 6) | G14: ala de serviço | H14: trancada | Q14: E a ala de serviço estava trancada. | R14: E a ala de serviço estava trancada! Ninguém pensou nisso? | S14: E a ala de serviço… trancada. | T14: E a ala de serviço estava trancada. Isso conta, não conta? | U14: E a ala de serviço estava trancada. | V14: Umidade nas paredes, um frio… E a ala de serviço estava trancada. | W14: Acrescente: a ala de serviço estava trancada. | X14: =SUMPRODUCT(($G14:$P14<>"")*ISERROR(SEARCH($G14:$P14,R14)))+SUMPRODUCT(($G14:$P14<>"")*ISERROR(SEARCH($G14:$P14,S14)))+SUMPRODUCT(($G14:$P14<>"")*ISERROR(SEARCH($G14:$P14,T14)))+SUMPRODUCT(($G14:$P14<>"")*ISERROR(SEARCH($G14:$P14,U14)))+SUMPRODUCT(($G14:$P14<>"")*ISERROR(SEARCH($G14:$P14,V14)))+SUMPRODUCT(($G14:$P14<>"")*ISERROR(SEARCH($G14:$P14,W14)))
A15: c1-14 | B15: a xícara no aparador (a Governanta vê primeiro) | C15: roteiro | D15: governanta | E15: grupo (citado na narração) | F15: partida com M.xicara=['governanta'] sem fala própria | G15: não é daqui | H15: louça da sala | I15: borda verde | J15: quarto dos fundos | Q15: Essa não é daqui. Não é da louça da sala. É o jogo de borda verde, o que ficava no quarto dos fundos. | R15: Essa não é daqui! Não é da louça da sala. É o jogo de borda verde, o que ficava no quarto dos fundos. | S15: Essa não é daqui… Não é da louça da sala. Borda verde… o jogo que ficava no quarto dos fundos. | T15: Essa não é daqui… Não é da louça da sala. É o jogo de borda verde, o que ficava no quarto dos fundos, não é? | U15: Essa não é daqui. Não é da louça da sala. É o jogo de borda verde, o que ficava no quarto dos fundos. Disso eu tenho certeza. | V15: Essa não é daqui. Tanta umidade, estraga tudo… Não é da louça da sala. É o jogo de borda verde, o que ficava no quarto dos fundos. | W15: Anoto: essa não é daqui. Não é da louça da sala. Jogo de borda verde, o que ficava no quarto dos fundos. | X15: =SUMPRODUCT(($G15:$P15<>"")*ISERROR(SEARCH($G15:$P15,R15)))+SUMPRODUCT(($G15:$P15<>"")*ISERROR(SEARCH($G15:$P15,S15)))+SUMPRODUCT(($G15:$P15<>"")*ISERROR(SEARCH($G15:$P15,T15)))+SUMPRODUCT(($G15:$P15<>"")*ISERROR(SEARCH($G15:$P15,U15)))+SUMPRODUCT(($G15:$P15<>"")*ISERROR(SEARCH($G15:$P15,V15)))+SUMPRODUCT(($G15:$P15<>"")*ISERROR(SEARCH($G15:$P15,W15))) | Y15: Enquadre: '{Gov} foi quem viu primeiro: <i>"fala"</i>'. Primeira de três falas seguidas (ver as duas próximas).
A16: c1-15 | B16: a xícara no aparador (a Governanta vê primeiro) | C16: roteiro | D16: policial | E16: governanta (citado na narração) | F16: partida com M.xicara=['governanta'] sem fala própria | G16: conhece bem a louça | H16: fechada | I16: cinco meses | Q16: Você conhece bem a louça de uma casa fechada há cinco meses | R16: Ora! Você conhece bem a louça de uma casa fechada há cinco meses | S16: Você conhece bem a louça… de uma casa fechada há cinco meses | T16: Você conhece bem a louça de uma casa fechada há cinco meses… que memória, não é? | U16: Você conhece bem a louça de uma casa fechada há cinco meses | V16: A senhora, com essa umidade toda, conhece bem a louça de uma casa fechada há cinco meses | W16: Anoto que você conhece bem a louça de uma casa fechada há cinco meses | X16: =SUMPRODUCT(($G16:$P16<>"")*ISERROR(SEARCH($G16:$P16,R16)))+SUMPRODUCT(($G16:$P16<>"")*ISERROR(SEARCH($G16:$P16,S16)))+SUMPRODUCT(($G16:$P16<>"")*ISERROR(SEARCH($G16:$P16,T16)))+SUMPRODUCT(($G16:$P16<>"")*ISERROR(SEARCH($G16:$P16,U16)))+SUMPRODUCT(($G16:$P16<>"")*ISERROR(SEARCH($G16:$P16,V16)))+SUMPRODUCT(($G16:$P16<>"")*ISERROR(SEARCH($G16:$P16,W16))) | Y16: Enquadre: '<i>"fala"</i>, disse {pol}.' A base não tem pontuação final porque a narração segue com vírgula; manter a versão sem ponto final se possível.
A17: c1-16 | B17: a xícara no aparador (a Governanta vê primeiro) | C17: roteiro | D17: governanta | E17: policial (citado na narração) | F17: partida com M.xicara=['governanta'] sem fala própria | G17: conheço a louça | H17: a casa | I17: já não sei | Q17: Conheço a louça. A casa, eu já não sei. | R17: Conheço a louça! A casa, eu já não sei. Satisfeito? | S17: Conheço a louça. A casa… já não sei. | T17: Conheço a louça… A casa, eu já não sei. Desculpe. | U17: Conheço a louça. A casa, eu já não sei, e me dói dizer. | V17: Ah, essa umidade… Conheço a louça. A casa, eu já não sei. | W17: Conheço a louça: confirmado. A casa, eu já não sei: sem registro. | X17: =SUMPRODUCT(($G17:$P17<>"")*ISERROR(SEARCH($G17:$P17,R17)))+SUMPRODUCT(($G17:$P17<>"")*ISERROR(SEARCH($G17:$P17,S17)))+SUMPRODUCT(($G17:$P17<>"")*ISERROR(SEARCH($G17:$P17,T17)))+SUMPRODUCT(($G17:$P17<>"")*ISERROR(SEARCH($G17:$P17,U17)))+SUMPRODUCT(($G17:$P17<>"")*ISERROR(SEARCH($G17:$P17,V17)))+SUMPRODUCT(($G17:$P17<>"")*ISERROR(SEARCH($G17:$P17,W17)))
A18: c1-17 | B18: a xícara no aparador (outro personagem vê primeiro) | C18: roteiro | D18: M.xicara[0] (observadora | governanta | herdeira | chefe_de_cozinha) | E18: grupo (citado na narração) | F18: partidas em que não vale o bloco da Governanta sem fala | G18: louça da sala | H18: outro jogo | I18: borda verde | Q18: Essa não é da louça da sala. É de outro jogo, de borda verde. | R18: Essa não é da louça da sala! É de outro jogo, de borda verde, ninguém viu? | S18: Essa não é da louça da sala… Outro jogo. Borda verde. | T18: Essa não é da louça da sala… É de outro jogo, de borda verde. Alguém mais reparou? | U18: Essa não é da louça da sala. É de outro jogo, de borda verde. | V18: Cansaço nenhum me engana: essa não é da louça da sala. É de outro jogo, de borda verde. | W18: Registre: não pertence à louça da sala. Outro jogo, borda verde. | X18: =SUMPRODUCT(($G18:$P18<>"")*ISERROR(SEARCH($G18:$P18,R18)))+SUMPRODUCT(($G18:$P18<>"")*ISERROR(SEARCH($G18:$P18,S18)))+SUMPRODUCT(($G18:$P18<>"")*ISERROR(SEARCH($G18:$P18,T18)))+SUMPRODUCT(($G18:$P18<>"")*ISERROR(SEARCH($G18:$P18,U18)))+SUMPRODUCT(($G18:$P18<>"")*ISERROR(SEARCH($G18:$P18,V18)))+SUMPRODUCT(($G18:$P18<>"")*ISERROR(SEARCH($G18:$P18,W18))) | Y18: Enquadre: '{Xq} foi quem viu primeiro: <i>"fala"</i>'. Falante varia (inclui o Chefe na P15): sem adjetivo de gênero. Nas P6/P7 segue a fala extra de MATRIZ_C1 (pendente por partida).
A19: c1-18 | B19: depois da xícara (com funcionários) | C19: chat | D19: voz(['herdeira','observadora','residente'],xq) | E19: grupo | F19: com funcionários | G19: ninguém do serviço | H19: xícara | I19: andou pela casa | J19: esta noite | Q19: Se ninguém do serviço deixou essa xícara ali, alguém andou pela casa esta noite. | R19: Se ninguém do serviço deixou essa xícara ali, alguém andou pela casa esta noite! Simples assim. | S19: Se ninguém do serviço deixou essa xícara… alguém andou pela casa. Esta noite. | T19: Se ninguém do serviço deixou essa xícara ali, então alguém andou pela casa esta noite? Que medo. | U19: Se ninguém do serviço deixou essa xícara ali, alguém andou pela casa esta noite. Na casa dele. | V19: Noite de chuva, ninguém dorme direito… Se ninguém do serviço deixou essa xícara ali, alguém andou pela casa esta noite. | W19: Hipótese: se ninguém do serviço deixou essa xícara ali, alguém andou pela casa esta noite. | X19: =SUMPRODUCT(($G19:$P19<>"")*ISERROR(SEARCH($G19:$P19,R19)))+SUMPRODUCT(($G19:$P19<>"")*ISERROR(SEARCH($G19:$P19,S19)))+SUMPRODUCT(($G19:$P19<>"")*ISERROR(SEARCH($G19:$P19,T19)))+SUMPRODUCT(($G19:$P19<>"")*ISERROR(SEARCH($G19:$P19,U19)))+SUMPRODUCT(($G19:$P19<>"")*ISERROR(SEARCH($G19:$P19,V19)))+SUMPRODUCT(($G19:$P19<>"")*ISERROR(SEARCH($G19:$P19,W19)))
A20: c1-19 | B20: depois da xícara (sem funcionários) | C20: chat | D20: voz(['herdeira','observadora','residente'],xq) | E20: grupo | F20: sem funcionários (casa de 6) | G20: xícara com café | H20: casa fechada | I20: esteve aqui hoje | Q20: Xícara com café numa casa fechada. Alguém esteve aqui hoje. | R20: Xícara com café numa casa fechada! Alguém esteve aqui hoje, é óbvio. | S20: Xícara com café… numa casa fechada. Alguém esteve aqui hoje. | T20: Uma xícara com café numa casa fechada… então alguém esteve aqui hoje, não é? | U20: Xícara com café numa casa fechada. Alguém esteve aqui hoje. | V20: Xícara com café numa casa fechada. E lá fora essa demora toda… Alguém esteve aqui hoje. | W20: Xícara com café numa casa fechada. Logo: alguém esteve aqui hoje. | X20: =SUMPRODUCT(($G20:$P20<>"")*ISERROR(SEARCH($G20:$P20,R20)))+SUMPRODUCT(($G20:$P20<>"")*ISERROR(SEARCH($G20:$P20,S20)))+SUMPRODUCT(($G20:$P20<>"")*ISERROR(SEARCH($G20:$P20,T20)))+SUMPRODUCT(($G20:$P20<>"")*ISERROR(SEARCH($G20:$P20,U20)))+SUMPRODUCT(($G20:$P20<>"")*ISERROR(SEARCH($G20:$P20,V20)))+SUMPRODUCT(($G20:$P20<>"")*ISERROR(SEARCH($G20:$P20,W20)))
A21: c1-20 | B21: o relógio bate sete horas | C21: roteiro | D21: policial | E21: grupo (citado na narração) | F21: todas as partidas exceto relogioP15 | G21: quatro minutos | H21: na frente | Q21: Está quatro minutos na frente. | R21: Está quatro minutos na frente! Quatro. | S21: Quatro minutos… na frente. | T21: Está quatro minutos na frente… isso é normal? | U21: Está quatro minutos na frente. | V21: Hum. Está quatro minutos na frente. | W21: Diferença: quatro minutos na frente. | X21: =SUMPRODUCT(($G21:$P21<>"")*ISERROR(SEARCH($G21:$P21,R21)))+SUMPRODUCT(($G21:$P21<>"")*ISERROR(SEARCH($G21:$P21,S21)))+SUMPRODUCT(($G21:$P21<>"")*ISERROR(SEARCH($G21:$P21,T21)))+SUMPRODUCT(($G21:$P21<>"")*ISERROR(SEARCH($G21:$P21,U21)))+SUMPRODUCT(($G21:$P21<>"")*ISERROR(SEARCH($G21:$P21,V21)))+SUMPRODUCT(($G21:$P21<>"")*ISERROR(SEARCH($G21:$P21,W21))) | Y21: Enquadre: '{Pol} olhou o próprio pulso: <i>"fala"</i>'.
A22: c1-21 | B22: o relógio bate sete horas | C22: roteiro | D22: herdeira | E22: policial (citado na narração) | F22: todas as partidas exceto relogioP15 | G22: sempre | H22: esteve | Q22: Sempre esteve | R22: Sempre esteve! | S22: Sempre… esteve. | T22: Sempre esteve… | U22: Sempre esteve. | V22: Bem… sempre esteve | W22: Sempre esteve. | X22: =SUMPRODUCT(($G22:$P22<>"")*ISERROR(SEARCH($G22:$P22,R22)))+SUMPRODUCT(($G22:$P22<>"")*ISERROR(SEARCH($G22:$P22,S22)))+SUMPRODUCT(($G22:$P22<>"")*ISERROR(SEARCH($G22:$P22,T22)))+SUMPRODUCT(($G22:$P22<>"")*ISERROR(SEARCH($G22:$P22,U22)))+SUMPRODUCT(($G22:$P22<>"")*ISERROR(SEARCH($G22:$P22,V22)))+SUMPRODUCT(($G22:$P22<>"")*ISERROR(SEARCH($G22:$P22,W22))) | Y22: Enquadre: '<i>"fala"</i>, disse {her}, e se arrependeu de ter dito.' A narração segue com vírgula; o deslize (conhecer o relógio) tem de ficar em todas.
A23: c1-22 | B23: o relógio bate sete horas (P15) | C23: roteiro | D23: policial | E23: grupo (citado na narração) | F23: relogioP15 (partida 15) | G23: continua | H23: quatro minutos | I23: na frente | J23: ele gostava assim | Q23: Continua quatro minutos na frente. Ele gostava assim. | R23: Continua quatro minutos na frente! Ele gostava assim, pronto. | S23: Continua… quatro minutos na frente. Ele gostava assim. | T23: Continua quatro minutos na frente… Ele gostava assim, não gostava? | U23: Continua quatro minutos na frente. Ele gostava assim, e assim deve ficar. | V23: Continua quatro minutos na frente. A gente perde a noção com esse tempo… Ele gostava assim. | W23: Continua quatro minutos na frente. Anoto: ele gostava assim. | X23: =SUMPRODUCT(($G23:$P23<>"")*ISERROR(SEARCH($G23:$P23,R23)))+SUMPRODUCT(($G23:$P23<>"")*ISERROR(SEARCH($G23:$P23,S23)))+SUMPRODUCT(($G23:$P23<>"")*ISERROR(SEARCH($G23:$P23,T23)))+SUMPRODUCT(($G23:$P23<>"")*ISERROR(SEARCH($G23:$P23,U23)))+SUMPRODUCT(($G23:$P23<>"")*ISERROR(SEARCH($G23:$P23,V23)))+SUMPRODUCT(($G23:$P23<>"")*ISERROR(SEARCH($G23:$P23,W23))) | Y23: Enquadre: '{Pol} acertou o pulso: <i>"fala"</i>'.
A24: c1-23 | B24: o relógio bate sete horas (P15) | C24: roteiro | D24: herdeira | E24: policial (citado na narração) | F24: relogioP15 (partida 15) | G24: continua | H24: você disse | I24: nunca tinha entrado aqui | Q24: Continua? Você disse que nunca tinha entrado aqui. | R24: Continua? Você disse que nunca tinha entrado aqui, ora! | S24: Continua? Você disse… que nunca tinha entrado aqui. | T24: Continua? Mas… você disse que nunca tinha entrado aqui, não disse? | U24: Continua? Você disse que nunca tinha entrado aqui. | V24: Continua? Essa chuva confunde a gente… mas você disse que nunca tinha entrado aqui. | W24: Continua? Consta que você disse que nunca tinha entrado aqui. | X24: =SUMPRODUCT(($G24:$P24<>"")*ISERROR(SEARCH($G24:$P24,R24)))+SUMPRODUCT(($G24:$P24<>"")*ISERROR(SEARCH($G24:$P24,S24)))+SUMPRODUCT(($G24:$P24<>"")*ISERROR(SEARCH($G24:$P24,T24)))+SUMPRODUCT(($G24:$P24<>"")*ISERROR(SEARCH($G24:$P24,U24)))+SUMPRODUCT(($G24:$P24<>"")*ISERROR(SEARCH($G24:$P24,V24)))+SUMPRODUCT(($G24:$P24<>"")*ISERROR(SEARCH($G24:$P24,W24))) | Y24: No código são duas citações: '<i>"Continua?"</i>, disse {her}. <i>"O senhor disse..."</i>'. Juntei numa fala; ao montar, a primeira frase (até o primeiro '?') vai antes de ', disse {her}.' e o resto depois.
A25: c1-24 | B25: o relógio bate sete horas (P15) | C25: roteiro | D25: policial | E25: herdeira (citado na narração) | F25: relogioP15 (partida 15) | G25: ouvi | H25: dizer | Q25: Ouvi dizer. | R25: Ouvi dizer! | S25: Ouvi… dizer. | T25: Ouvi dizer… | U25: Ouvi dizer. | V25: Ah… ouvi dizer. | W25: Ouvi dizer. | X25: =SUMPRODUCT(($G25:$P25<>"")*ISERROR(SEARCH($G25:$P25,R25)))+SUMPRODUCT(($G25:$P25<>"")*ISERROR(SEARCH($G25:$P25,S25)))+SUMPRODUCT(($G25:$P25<>"")*ISERROR(SEARCH($G25:$P25,T25)))+SUMPRODUCT(($G25:$P25<>"")*ISERROR(SEARCH($G25:$P25,U25)))+SUMPRODUCT(($G25:$P25<>"")*ISERROR(SEARCH($G25:$P25,V25)))+SUMPRODUCT(($G25:$P25<>"")*ISERROR(SEARCH($G25:$P25,W25)))
A26: c1-25 | B26: a Observadora se aproxima do relógio | C26: roteiro | D26: observadora | E26: grupo (citado na narração) | G26: nunca vi | H26: de perto | I26: fotografias do inventário | J26: mais bonita | Q26: Nunca vi esta peça de perto. Só pelas fotografias do inventário. É mais bonita do que parece no papel. | R26: Nunca vi esta peça de perto, só pelas fotografias do inventário! É mais bonita do que parece no papel. | S26: Nunca vi esta peça de perto… Só pelas fotografias do inventário. Mais bonita… do que no papel. | T26: Nunca vi esta peça de perto… só pelas fotografias do inventário. É mais bonita do que parece no papel, não acham? | U26: Nunca vi esta peça de perto. Só pelas fotografias do inventário. É mais bonita do que parece no papel. | V26: Que cansaço, esta noite… Nunca vi esta peça de perto. Só pelas fotografias do inventário. É mais bonita do que parece no papel. | W26: Nunca vi esta peça de perto. Só pelas fotografias do inventário. Nota: mais bonita do que parece no papel. | X26: =SUMPRODUCT(($G26:$P26<>"")*ISERROR(SEARCH($G26:$P26,R26)))+SUMPRODUCT(($G26:$P26<>"")*ISERROR(SEARCH($G26:$P26,S26)))+SUMPRODUCT(($G26:$P26<>"")*ISERROR(SEARCH($G26:$P26,T26)))+SUMPRODUCT(($G26:$P26<>"")*ISERROR(SEARCH($G26:$P26,U26)))+SUMPRODUCT(($G26:$P26<>"")*ISERROR(SEARCH($G26:$P26,V26)))+SUMPRODUCT(($G26:$P26<>"")*ISERROR(SEARCH($G26:$P26,W26))) | Y26: Enquadre: '{Obs} se aproximou do móvel com as mãos para trás, como se tivesse medo de tocar. <i>"fala"</i>'.
A27: c1-26 | B27: depois do relógio | C27: chat | D27: voz(['jornalista','residente','herdeira']) | E27: grupo | G27: relógio de corda | H27: sozinho | I27: anotem | Q27: Relógio de corda andando sozinho. Anotem isso. | R27: Relógio de corda andando sozinho! Anotem isso. | S27: Relógio de corda… andando sozinho. Anotem. | T27: Relógio de corda andando sozinho… Anotem isso, por favor? Que esquisito. | U27: Relógio de corda andando sozinho. Anotem isso. | V27: Relógio de corda andando sozinho. Tanta demora pra chegar, e agora isso… Anotem isso. | W27: Item para a ata: relógio de corda andando sozinho. Anotem. | X27: =SUMPRODUCT(($G27:$P27<>"")*ISERROR(SEARCH($G27:$P27,R27)))+SUMPRODUCT(($G27:$P27<>"")*ISERROR(SEARCH($G27:$P27,S27)))+SUMPRODUCT(($G27:$P27<>"")*ISERROR(SEARCH($G27:$P27,T27)))+SUMPRODUCT(($G27:$P27<>"")*ISERROR(SEARCH($G27:$P27,U27)))+SUMPRODUCT(($G27:$P27<>"")*ISERROR(SEARCH($G27:$P27,V27)))+SUMPRODUCT(($G27:$P27<>"")*ISERROR(SEARCH($G27:$P27,W27)))
A28: c1-27 | B28: o Porto da adega (deslize de quem voltou) | C28: roteiro | D28: chefe_de_cozinha | E28: grupo (citado na narração) | F28: M.voltou[1]==='porto' (partidas 8 e 12) | G28: levaram o porto | H28: depois do enterro | I28: três garrafas | J28: oitenta e dois | Q28: Levaram o Porto. Depois do enterro ainda tinha três garrafas de oitenta e dois. | R28: Levaram o Porto! Depois do enterro ainda tinha três garrafas de oitenta e dois. | S28: Levaram o Porto… Depois do enterro… ainda tinha três garrafas. De oitenta e dois. | T28: Levaram o Porto… Depois do enterro ainda tinha três garrafas de oitenta e dois, não tinha? | U28: Levaram o Porto. Depois do enterro ainda tinha três garrafas de oitenta e dois. | V28: Levaram o Porto. Adega fria, úmida… Depois do enterro ainda tinha três garrafas de oitenta e dois. | W28: Levaram o Porto. Depois do enterro, constavam ainda três garrafas de oitenta e dois. | X28: =SUMPRODUCT(($G28:$P28<>"")*ISERROR(SEARCH($G28:$P28,R28)))+SUMPRODUCT(($G28:$P28<>"")*ISERROR(SEARCH($G28:$P28,S28)))+SUMPRODUCT(($G28:$P28<>"")*ISERROR(SEARCH($G28:$P28,T28)))+SUMPRODUCT(($G28:$P28<>"")*ISERROR(SEARCH($G28:$P28,U28)))+SUMPRODUCT(($G28:$P28<>"")*ISERROR(SEARCH($G28:$P28,V28)))+SUMPRODUCT(($G28:$P28<>"")*ISERROR(SEARCH($G28:$P28,W28))) | Y28: Enquadre: '{Che} tinha ido à adega... Voltou com duas garrafas e uma cara estranha: <i>"fala"</i>'. O deslize (saber o que havia depois do enterro) fica em todas.
A29: c1-28 | B29: o Porto da adega (deslize de quem voltou) | C29: roteiro | D29: investigador | E29: chefe_de_cozinha (citado na narração) | F29: M.voltou[1]==='porto' (partidas 8 e 12) | G29: depois do enterro | H29: lacrada | I29: como o senhor sabe | Q29: Depois do enterro a casa já estava lacrada. Como é que você sabe? | R29: Depois do enterro a casa já estava lacrada! Como é que você sabe, hein? | S29: Depois do enterro… a casa já estava lacrada. Como é que você sabe? | T29: Mas depois do enterro a casa já estava lacrada, não estava? Como é que você sabe? | U29: Depois do enterro a casa já estava lacrada. Como é que você sabe? | V29: Pois é, a demora toda… Depois do enterro a casa já estava lacrada. Como é que você sabe? | W29: Data: depois do enterro, a casa já estava lacrada. Como é que você sabe? | X29: =SUMPRODUCT(($G29:$P29<>"")*ISERROR(SEARCH($G29:$P29,R29)))+SUMPRODUCT(($G29:$P29<>"")*ISERROR(SEARCH($G29:$P29,S29)))+SUMPRODUCT(($G29:$P29<>"")*ISERROR(SEARCH($G29:$P29,T29)))+SUMPRODUCT(($G29:$P29<>"")*ISERROR(SEARCH($G29:$P29,U29)))+SUMPRODUCT(($G29:$P29<>"")*ISERROR(SEARCH($G29:$P29,V29)))+SUMPRODUCT(($G29:$P29<>"")*ISERROR(SEARCH($G29:$P29,W29))) | Y29: Enquadre: '<i>"fala"</i>, perguntou {inv}.'
A30: c1-29 | B30: a maçaneta desce por dentro | C30: roteiro | D30: eletricista | residente (o Eletricista se estiver na casa) | E30: grupo (citado na narração) | G30: porta | H30: não tem mola | Q30: Essa porta não tem mola. | R30: Essa porta não tem mola. Não tem. | S30: Essa porta… não tem mola. | T30: Essa porta não tem mola… sabiam? | U30: Essa porta não tem mola. | V30: Cansaço à parte… essa porta não tem mola. | W30: Anoto: essa porta não tem mola. | X30: =SUMPRODUCT(($G30:$P30<>"")*ISERROR(SEARCH($G30:$P30,R30)))+SUMPRODUCT(($G30:$P30<>"")*ISERROR(SEARCH($G30:$P30,S30)))+SUMPRODUCT(($G30:$P30<>"")*ISERROR(SEARCH($G30:$P30,T30)))+SUMPRODUCT(($G30:$P30<>"")*ISERROR(SEARCH($G30:$P30,U30)))+SUMPRODUCT(($G30:$P30<>"")*ISERROR(SEARCH($G30:$P30,V30)))+SUMPRODUCT(($G30:$P30<>"")*ISERROR(SEARCH($G30:$P30,W30))) | Y30: Enquadre: '{X} foi o primeiro a falar, e falou baixo: <i>"fala"</i>'. A narração diz 'falou baixo' para qualquer tipo; o explosivo fica em tensão com isso (ver dúvidas).
A31: c1-30 | B31: depois da maçaneta | C31: chat | D31: voz(['policial','residente']) | E31: grupo | G31: ninguém | H31: aquela porta | I31: sozinho | Q31: Ninguém vai até aquela porta sozinho. | R31: Ninguém vai até aquela porta sozinho! Nem pensar. | S31: Ninguém vai… até aquela porta. Sozinho, não. | T31: Ninguém vai até aquela porta sozinho, tá? É mais seguro assim. | U31: Ninguém vai até aquela porta sozinho. | V31: Com esse cansaço todo… ninguém vai até aquela porta sozinho. | W31: Norma a partir de agora: ninguém vai até aquela porta sozinho. | X31: =SUMPRODUCT(($G31:$P31<>"")*ISERROR(SEARCH($G31:$P31,R31)))+SUMPRODUCT(($G31:$P31<>"")*ISERROR(SEARCH($G31:$P31,S31)))+SUMPRODUCT(($G31:$P31<>"")*ISERROR(SEARCH($G31:$P31,T31)))+SUMPRODUCT(($G31:$P31<>"")*ISERROR(SEARCH($G31:$P31,U31)))+SUMPRODUCT(($G31:$P31<>"")*ISERROR(SEARCH($G31:$P31,V31)))+SUMPRODUCT(($G31:$P31<>"")*ISERROR(SEARCH($G31:$P31,W31)))
A32: c1-31 | B32: depois da maçaneta | C32: privado | D32: voz(['herdeira','jornalista','observadora'],M.macaneta) | E32: jogador no privado | G32: você viu | H32: aquela porta | I32: antes | Q32: Você viu quem foi até aquela porta antes? | R32: E aí, você viu quem foi até aquela porta antes ou não? | S32: Você viu… quem foi até aquela porta? Antes. | T32: Desculpa perguntar… você viu quem foi até aquela porta antes? | U32: Você viu quem foi até aquela porta antes? | V32: Que noite, essa chuva não para… Aliás, você viu quem foi até aquela porta antes? | W32: Ponto a esclarecer: você viu quem foi até aquela porta antes? | X32: =SUMPRODUCT(($G32:$P32<>"")*ISERROR(SEARCH($G32:$P32,R32)))+SUMPRODUCT(($G32:$P32<>"")*ISERROR(SEARCH($G32:$P32,S32)))+SUMPRODUCT(($G32:$P32<>"")*ISERROR(SEARCH($G32:$P32,T32)))+SUMPRODUCT(($G32:$P32<>"")*ISERROR(SEARCH($G32:$P32,U32)))+SUMPRODUCT(($G32:$P32<>"")*ISERROR(SEARCH($G32:$P32,V32)))+SUMPRODUCT(($G32:$P32<>"")*ISERROR(SEARCH($G32:$P32,W32)))
A33: c1-32 | B33: resposta a 'Quem chegou primeiro?' | C33: resposta | D33: voz(['residente','herdeira']) | E33: grupo | G33: ninguém sabe | H33: cada um | I33: já tinha gente aqui | Q33: Ninguém sabe. Cada um achou que já tinha gente aqui. | R33: Ninguém sabe! Cada um achou que já tinha gente aqui, que bagunça. | S33: Ninguém sabe… Cada um achou… que já tinha gente aqui. | T33: Ninguém sabe… cada um achou que já tinha gente aqui. Eu também, desculpa. | U33: Ninguém sabe. Cada um achou que já tinha gente aqui. | V33: Com essa chuva e essa demora… ninguém sabe. Cada um achou que já tinha gente aqui. | W33: Ninguém sabe. Consta que cada um achou que já tinha gente aqui. | X33: =SUMPRODUCT(($G33:$P33<>"")*ISERROR(SEARCH($G33:$P33,R33)))+SUMPRODUCT(($G33:$P33<>"")*ISERROR(SEARCH($G33:$P33,S33)))+SUMPRODUCT(($G33:$P33<>"")*ISERROR(SEARCH($G33:$P33,T33)))+SUMPRODUCT(($G33:$P33<>"")*ISERROR(SEARCH($G33:$P33,U33)))+SUMPRODUCT(($G33:$P33<>"")*ISERROR(SEARCH($G33:$P33,V33)))+SUMPRODUCT(($G33:$P33<>"")*ISERROR(SEARCH($G33:$P33,W33)))
A34: c1-33 | B34: resposta a 'De quem é a xícara com café?' | C34: resposta | D34: voz(['herdeira','residente','jornalista'],xq) | E34: grupo | G34: ninguém assumiu | H34: até agora | Q34: Ninguém assumiu até agora. | R34: Ninguém assumiu até agora! Que coragem a de vocês. | S34: Ninguém assumiu… até agora. | T34: Ninguém assumiu até agora… será que vai? | U34: Ninguém assumiu até agora. | V34: Bom… ninguém assumiu até agora. | W34: Ninguém assumiu até agora. Autoria: não registrada. | X34: =SUMPRODUCT(($G34:$P34<>"")*ISERROR(SEARCH($G34:$P34,R34)))+SUMPRODUCT(($G34:$P34<>"")*ISERROR(SEARCH($G34:$P34,S34)))+SUMPRODUCT(($G34:$P34<>"")*ISERROR(SEARCH($G34:$P34,T34)))+SUMPRODUCT(($G34:$P34<>"")*ISERROR(SEARCH($G34:$P34,U34)))+SUMPRODUCT(($G34:$P34<>"")*ISERROR(SEARCH($G34:$P34,V34)))+SUMPRODUCT(($G34:$P34<>"")*ISERROR(SEARCH($G34:$P34,W34)))
A35: c1-34 | B35: resposta a 'O relógio não devia estar parado?' | C35: resposta | D35: voz(['policial','residente']) | E35: grupo | G35: devia | H35: adiantado | Q35: Devia. E ainda está adiantado. | R35: Devia! E ainda por cima está adiantado. | S35: Devia… E ainda adiantado. | T35: Devia, não devia? E ainda está adiantado… | U35: Devia. E ainda está adiantado. | V35: Devia. E, com essa umidade toda, ainda está adiantado. | W35: Devia. Anoto: ainda está adiantado. | X35: =SUMPRODUCT(($G35:$P35<>"")*ISERROR(SEARCH($G35:$P35,R35)))+SUMPRODUCT(($G35:$P35<>"")*ISERROR(SEARCH($G35:$P35,S35)))+SUMPRODUCT(($G35:$P35<>"")*ISERROR(SEARCH($G35:$P35,T35)))+SUMPRODUCT(($G35:$P35<>"")*ISERROR(SEARCH($G35:$P35,U35)))+SUMPRODUCT(($G35:$P35<>"")*ISERROR(SEARCH($G35:$P35,V35)))+SUMPRODUCT(($G35:$P35<>"")*ISERROR(SEARCH($G35:$P35,W35)))
A36: c1-35 | B36: resposta a 'Quem estava perto do quarto de serviço?' | C36: resposta | D36: voz(['jornalista','herdeira','policial','residente'],M.macaneta) | E36: grupo | G36: sala do relógio | H36: com todos | I36: não vi ninguém sair | Q36: Eu estava na sala do relógio, com todos. Não vi ninguém sair. | R36: Eu estava na sala do relógio, com todos! Não vi ninguém sair, de novo isso? | S36: Eu estava na sala do relógio… com todos. Não vi ninguém sair. | T36: Eu estava na sala do relógio, com todos… Não vi ninguém sair. Alguém viu? | U36: Eu estava na sala do relógio, com todos. Não vi ninguém sair. | V36: Com essa chuva lá fora… Eu estava na sala do relógio, com todos. Não vi ninguém sair. | W36: Local: sala do relógio, com todos. Não vi ninguém sair. | X36: =SUMPRODUCT(($G36:$P36<>"")*ISERROR(SEARCH($G36:$P36,R36)))+SUMPRODUCT(($G36:$P36<>"")*ISERROR(SEARCH($G36:$P36,S36)))+SUMPRODUCT(($G36:$P36<>"")*ISERROR(SEARCH($G36:$P36,T36)))+SUMPRODUCT(($G36:$P36<>"")*ISERROR(SEARCH($G36:$P36,U36)))+SUMPRODUCT(($G36:$P36<>"")*ISERROR(SEARCH($G36:$P36,V36)))+SUMPRODUCT(($G36:$P36<>"")*ISERROR(SEARCH($G36:$P36,W36)))
A37: c1-36 | B37: resposta a 'A xícara prova que alguém mora aqui.' | C37: resposta | D37: voz(['observadora','herdeira']) | E37: grupo | G37: ou que | H37: esteve aqui hoje | Q37: Ou que alguém esteve aqui hoje. | R37: Ou que alguém esteve aqui hoje, ora! | S37: Ou que… alguém esteve aqui hoje. | T37: Ou que alguém esteve aqui hoje, não? | U37: Ou que alguém esteve aqui hoje. | V37: Ou que alguém esteve aqui hoje. | W37: Ou que alguém esteve aqui hoje. Segunda hipótese. | X37: =SUMPRODUCT(($G37:$P37<>"")*ISERROR(SEARCH($G37:$P37,R37)))+SUMPRODUCT(($G37:$P37<>"")*ISERROR(SEARCH($G37:$P37,S37)))+SUMPRODUCT(($G37:$P37<>"")*ISERROR(SEARCH($G37:$P37,T37)))+SUMPRODUCT(($G37:$P37<>"")*ISERROR(SEARCH($G37:$P37,U37)))+SUMPRODUCT(($G37:$P37<>"")*ISERROR(SEARCH($G37:$P37,V37)))+SUMPRODUCT(($G37:$P37<>"")*ISERROR(SEARCH($G37:$P37,W37)))
A38: c1-37 | B38: resposta a 'Alguém dá corda no relógio. Isso prova.' | C38: resposta | D38: voz(['residente','policial']) | E38: grupo | G38: relógio de corda | H38: cinco meses | I38: sozinho | Q38: Relógio de corda não anda cinco meses sozinho. | R38: Relógio de corda não anda cinco meses sozinho! Por favor. | S38: Relógio de corda… não anda cinco meses sozinho. | T38: Relógio de corda não anda cinco meses sozinho… anda? | U38: Relógio de corda não anda cinco meses sozinho. | V38: Essa umidade estraga tudo, mas relógio de corda não anda cinco meses sozinho. | W38: Fato técnico: relógio de corda não anda cinco meses sozinho. | X38: =SUMPRODUCT(($G38:$P38<>"")*ISERROR(SEARCH($G38:$P38,R38)))+SUMPRODUCT(($G38:$P38<>"")*ISERROR(SEARCH($G38:$P38,S38)))+SUMPRODUCT(($G38:$P38<>"")*ISERROR(SEARCH($G38:$P38,T38)))+SUMPRODUCT(($G38:$P38<>"")*ISERROR(SEARCH($G38:$P38,U38)))+SUMPRODUCT(($G38:$P38<>"")*ISERROR(SEARCH($G38:$P38,V38)))+SUMPRODUCT(($G38:$P38<>"")*ISERROR(SEARCH($G38:$P38,W38)))
A39: c1-38 | B39: resposta a 'Vamos ficar juntos.' | C39: resposta | D39: voz(['policial','herdeira']) | E39: grupo | G39: concordo | Q39: Concordo. | R39: Concordo! | S39: …concordo. | T39: Concordo… | U39: Concordo. | V39: Concordo. | W39: Concordo. | X39: =SUMPRODUCT(($G39:$P39<>"")*ISERROR(SEARCH($G39:$P39,R39)))+SUMPRODUCT(($G39:$P39<>"")*ISERROR(SEARCH($G39:$P39,S39)))+SUMPRODUCT(($G39:$P39<>"")*ISERROR(SEARCH($G39:$P39,T39)))+SUMPRODUCT(($G39:$P39<>"")*ISERROR(SEARCH($G39:$P39,U39)))+SUMPRODUCT(($G39:$P39<>"")*ISERROR(SEARCH($G39:$P39,V39)))+SUMPRODUCT(($G39:$P39<>"")*ISERROR(SEARCH($G39:$P39,W39))) | Y39: 'juntos' vem da pergunta do jogador; repete o que foi proposto, não acrescenta fato.
A40: c1-39 | B40: resposta a 'Por que ninguém avisou que havia funcionários?' | C40: resposta | D40: voz(FUNCIONARIOS) = governanta | E40: grupo | F40: com funcionários; um só funcionário (casa de 8) | G40: chamada | H40: preparar a casa | I40: ninguém disse para quem | Q40: Fui chamada para preparar a casa. Ninguém disse para quem. | R40: Fui chamada para preparar a casa! Ninguém disse para quem, querem o quê? | S40: Fui chamada… para preparar a casa. Ninguém disse para quem. | T40: Fui chamada para preparar a casa, só isso… ninguém disse para quem, desculpem. | U40: Fui chamada para preparar a casa, e a casa merece. Ninguém disse para quem. | V40: Fui chamada para preparar a casa. A estrada até aqui, um sofrimento… Ninguém disse para quem. | W40: Consta: fui chamada para preparar a casa. Ninguém disse para quem. | X40: =SUMPRODUCT(($G40:$P40<>"")*ISERROR(SEARCH($G40:$P40,R40)))+SUMPRODUCT(($G40:$P40<>"")*ISERROR(SEARCH($G40:$P40,S40)))+SUMPRODUCT(($G40:$P40<>"")*ISERROR(SEARCH($G40:$P40,T40)))+SUMPRODUCT(($G40:$P40<>"")*ISERROR(SEARCH($G40:$P40,U40)))+SUMPRODUCT(($G40:$P40<>"")*ISERROR(SEARCH($G40:$P40,V40)))+SUMPRODUCT(($G40:$P40<>"")*ISERROR(SEARCH($G40:$P40,W40)))
...

Sheet Cap 2
A1: ID | B1: Cena | C1: Momento | D1: Quem fala | E1: Com quem | F1: Condição | G1: Item 1 | H1: Item 2 | I1: Item 3 | J1: Item 4 | K1: Item 5 | L1: Item 6 | M1: Item 7 | N1: Item 8 | O1: Item 9 | P1: Item 10 | Q1: Fala original | R1: Explosivo | S1: Calmo opaco | T1: Ingênuo | U1: Leal cego | V1: Evasivo | W1: Burocrata | X1: Faltam | Y1: Nota
A2: c2-01 | B2: o rádio do farol avisa da ponte | C2: roteiro | D2: faroleiro | E2: a casa, pelo rádio | G2: farol | H2: ponte caiu | I2: cheia | J2: ninguém sobe nem desce | K2: de manhã | Q2: Casa da Costa, aqui é o farol. A ponte caiu com a cheia. Ninguém sobe nem desce até de manhã. Repito: ninguém sobe nem desce. | R2: Casa da Costa, é o farol! A ponte caiu com a cheia. Ninguém sobe nem desce até de manhã. Ninguém sobe nem desce, ouviram? | S2: Casa da Costa… aqui, o farol. A ponte caiu. A cheia. Ninguém sobe nem desce… até de manhã. Ninguém sobe nem desce. | T2: Casa da Costa? Aqui é o farol… A ponte caiu com a cheia. Ninguém sobe nem desce até de manhã. Ninguém sobe nem desce, tá? | U2: Casa da Costa, aqui é o farol. A ponte caiu com a cheia. Ninguém sobe nem desce até de manhã. Repito: ninguém sobe nem desce. | V2: Casa da Costa, aqui é o farol. Chove sem parar por aqui… A ponte caiu com a cheia. Ninguém sobe nem desce até de manhã. Ninguém sobe nem desce. | W2: Casa da Costa, farol na escuta. Ocorrência: a ponte caiu com a cheia. Ninguém sobe nem desce até de manhã. Repito: ninguém sobe nem desce. | X2: =SUMPRODUCT(($G2:$P2<>"")*ISERROR(SEARCH($G2:$P2,R2)))+SUMPRODUCT(($G2:$P2<>"")*ISERROR(SEARCH($G2:$P2,S2)))+SUMPRODUCT(($G2:$P2<>"")*ISERROR(SEARCH($G2:$P2,T2)))+SUMPRODUCT(($G2:$P2<>"")*ISERROR(SEARCH($G2:$P2,U2)))+SUMPRODUCT(($G2:$P2<>"")*ISERROR(SEARCH($G2:$P2,V2)))+SUMPRODUCT(($G2:$P2<>"")*ISERROR(SEARCH($G2:$P2,W2))) | Y2: Primeira fala citada da narração (enquadre: "A voz do Faroleiro veio cortada pela estática, mas firme"). "Casa da Costa" é o nome da casa usado como chamada de rádio, não de personagem.
A3: c2-02 | B3: o rádio do farol avisa da ponte | C3: roteiro | D3: investigador | E3: faroleiro, pelo rádio | G3: entendido | H3: luz | Q3: Entendido. Tem luz aí? | R3: Entendido. Tem luz aí?! | S3: Entendido… Tem luz aí? | T3: Entendido. Tem luz aí…? | U3: Entendido. Tem luz aí? | V3: Ah… entendido. Tem luz aí? | W3: Entendido. Tem luz aí? | X3: =SUMPRODUCT(($G3:$P3<>"")*ISERROR(SEARCH($G3:$P3,R3)))+SUMPRODUCT(($G3:$P3<>"")*ISERROR(SEARCH($G3:$P3,S3)))+SUMPRODUCT(($G3:$P3<>"")*ISERROR(SEARCH($G3:$P3,T3)))+SUMPRODUCT(($G3:$P3<>"")*ISERROR(SEARCH($G3:$P3,U3)))+SUMPRODUCT(($G3:$P3<>"")*ISERROR(SEARCH($G3:$P3,V3)))+SUMPRODUCT(($G3:$P3<>"")*ISERROR(SEARCH($G3:$P3,W3))) | Y3: Fala do Investigador (ele alcançou o rádio). A narração não marca o falante; deduzido pelo contexto.
A4: c2-03 | B4: o rádio do farol avisa da ponte | C4: roteiro | D4: faroleiro | E4: a casa, pelo rádio | G4: farol | H4: gerador | I4: costa | J4: não sei por quanto tempo | Q4: O farol tem gerador. A costa, não sei por quanto tempo. | R4: O farol tem gerador! A costa, não sei por quanto tempo, e não me peçam milagre. | S4: O farol… tem gerador. A costa… não sei por quanto tempo. | T4: O farol tem gerador, isso eu sei. A costa… não sei por quanto tempo, desculpa. | U4: O farol tem gerador. A costa, não sei por quanto tempo. | V4: O farol tem gerador. Com esse frio, essa umidade… a costa, não sei por quanto tempo. | W4: Situação: o farol tem gerador. A costa, não sei por quanto tempo. | X4: =SUMPRODUCT(($G4:$P4<>"")*ISERROR(SEARCH($G4:$P4,R4)))+SUMPRODUCT(($G4:$P4<>"")*ISERROR(SEARCH($G4:$P4,S4)))+SUMPRODUCT(($G4:$P4<>"")*ISERROR(SEARCH($G4:$P4,T4)))+SUMPRODUCT(($G4:$P4<>"")*ISERROR(SEARCH($G4:$P4,U4)))+SUMPRODUCT(($G4:$P4<>"")*ISERROR(SEARCH($G4:$P4,V4)))+SUMPRODUCT(($G4:$P4<>"")*ISERROR(SEARCH($G4:$P4,W4)))
A5: c2-04 | B5: a ponte caiu | C5: chat | D5: voz(['herdeira','advogado','jornalista']) | E5: grupo | G5: ponte caiu | H5: ninguém vai embora | Q5: A ponte caiu. Então ninguém vai embora. | R5: A ponte caiu! Pronto, ninguém vai embora, que beleza. | S5: A ponte caiu… Então… ninguém vai embora. | T5: A ponte caiu… então ninguém vai embora? Nossa. | U5: A ponte caiu. Então ninguém vai embora. | V5: A ponte caiu. Essa chuva, essa estrada… Então ninguém vai embora. | W5: Consta: a ponte caiu. Consequência: ninguém vai embora. | X5: =SUMPRODUCT(($G5:$P5<>"")*ISERROR(SEARCH($G5:$P5,R5)))+SUMPRODUCT(($G5:$P5<>"")*ISERROR(SEARCH($G5:$P5,S5)))+SUMPRODUCT(($G5:$P5<>"")*ISERROR(SEARCH($G5:$P5,T5)))+SUMPRODUCT(($G5:$P5<>"")*ISERROR(SEARCH($G5:$P5,U5)))+SUMPRODUCT(($G5:$P5<>"")*ISERROR(SEARCH($G5:$P5,V5)))+SUMPRODUCT(($G5:$P5<>"")*ISERROR(SEARCH($G5:$P5,W5)))
A6: c2-05 | B6: a luz no corredor de serviço | C6: roteiro | D6: quem viu a luz (MATRIZ_C2.luz) | E6: sala | G6: alguém lá | Q6: Tem alguém lá. | R6: Tem alguém lá! | S6: Tem… alguém lá. | T6: Tem alguém lá… | U6: Tem alguém lá. | V6: Tem alguém lá. | W6: Tem alguém lá. | X6: =SUMPRODUCT(($G6:$P6<>"")*ISERROR(SEARCH($G6:$P6,R6)))+SUMPRODUCT(($G6:$P6<>"")*ISERROR(SEARCH($G6:$P6,S6)))+SUMPRODUCT(($G6:$P6<>"")*ISERROR(SEARCH($G6:$P6,T6)))+SUMPRODUCT(($G6:$P6<>"")*ISERROR(SEARCH($G6:$P6,U6)))+SUMPRODUCT(($G6:$P6<>"")*ISERROR(SEARCH($G6:$P6,V6)))+SUMPRODUCT(($G6:$P6<>"")*ISERROR(SEARCH($G6:$P6,W6))) | Y6: Fala citada na narração; falante é M.luz (varia por partida), texto fixo. Não usar adjetivo de gênero.
A7: c2-06 | B7: a luz no corredor de serviço | C7: roteiro | D7: tabeliao | policial | residente (quem não viu a luz) | E7: sala | G7: porta trancada | H7: diferente | Q7: Tem uma porta trancada lá. O que é diferente. | R7: Tem uma porta trancada lá! O que é bem diferente. | S7: Tem uma porta trancada lá… O que é diferente. | T7: Tem uma porta trancada lá… o que é diferente, não é? | U7: Tem uma porta trancada lá. O que é diferente. | V7: Olha, com esse cansaço todo… tem uma porta trancada lá. O que é diferente. | W7: Correção: tem uma porta trancada lá. O que é diferente. | X7: =SUMPRODUCT(($G7:$P7<>"")*ISERROR(SEARCH($G7:$P7,R7)))+SUMPRODUCT(($G7:$P7<>"")*ISERROR(SEARCH($G7:$P7,S7)))+SUMPRODUCT(($G7:$P7<>"")*ISERROR(SEARCH($G7:$P7,T7)))+SUMPRODUCT(($G7:$P7<>"")*ISERROR(SEARCH($G7:$P7,U7)))+SUMPRODUCT(($G7:$P7<>"")*ISERROR(SEARCH($G7:$P7,V7)))+SUMPRODUCT(($G7:$P7<>"")*ISERROR(SEARCH($G7:$P7,W7))) | Y7: Enquadre: "corrigiu X". Falante: tabelião se presente e não for M.luz; senão policial; senão residente. Gênero variável.
A8: c2-07 | B8: a voz a mais chega ao grupo | C8: voz | D8: acompanhante | E8: grupo | G8: boa noite | Q8: Boa noite. | R8: Boa noite. | S8: … Boa noite. | T8: Boa noite. | U8: Boa noite. | V8: Boa noite. | W8: Boa noite. | X8: =SUMPRODUCT(($G8:$P8<>"")*ISERROR(SEARCH($G8:$P8,R8)))+SUMPRODUCT(($G8:$P8<>"")*ISERROR(SEARCH($G8:$P8,S8)))+SUMPRODUCT(($G8:$P8<>"")*ISERROR(SEARCH($G8:$P8,T8)))+SUMPRODUCT(($G8:$P8<>"")*ISERROR(SEARCH($G8:$P8,U8)))+SUMPRODUCT(($G8:$P8<>"")*ISERROR(SEARCH($G8:$P8,V8)))+SUMPRODUCT(($G8:$P8<>"")*ISERROR(SEARCH($G8:$P8,W8))) | Y8: Função: chegada da voz, sem se apresentar. O código diz que a chegada é igual para todas as personalidades; mantive igual nos 6 (só o calmo_opaco com reticência). Decidir se deve variar.
A9: c2-08 | B9: a voz a mais chega ao grupo | C9: chat | D9: voz(['jornalista','policial']) | E9: grupo | G9: número | Q9: Quem é esse número? | R9: Quem é esse número?! | S9: Quem… é esse número? | T9: Quem é esse número…? | U9: Quem é esse número? | V9: Hum… quem é esse número? | W9: Quem é esse número? | X9: =SUMPRODUCT(($G9:$P9<>"")*ISERROR(SEARCH($G9:$P9,R9)))+SUMPRODUCT(($G9:$P9<>"")*ISERROR(SEARCH($G9:$P9,S9)))+SUMPRODUCT(($G9:$P9<>"")*ISERROR(SEARCH($G9:$P9,T9)))+SUMPRODUCT(($G9:$P9<>"")*ISERROR(SEARCH($G9:$P9,U9)))+SUMPRODUCT(($G9:$P9<>"")*ISERROR(SEARCH($G9:$P9,V9)))+SUMPRODUCT(($G9:$P9<>"")*ISERROR(SEARCH($G9:$P9,W9)))
A10: c2-09 | B10: a chamada no grupo | C10: roteiro | D10: quem conduz (MATRIZ_C2.conduz) | E10: sala | G10: direito | H10: uma palavra no grupo | I10: ordem da roda | J10: sobrou | Q10: Vamos fazer isso direito. Cada um manda uma palavra no grupo, na ordem da roda. Quem sobrar, sobrou. | R10: Vamos fazer isso direito, chega! Cada um manda uma palavra no grupo, na ordem da roda. Quem sobrar, sobrou. | S10: Vamos fazer direito… Cada um… uma palavra no grupo. Na ordem da roda. Quem sobrar… sobrou. | T10: Vamos fazer isso direito, pode ser? Cada um manda uma palavra no grupo, na ordem da roda… quem sobrar, sobrou, tá? | U10: Vamos fazer isso direito. Cada um manda uma palavra no grupo, na ordem da roda. Quem sobrar, sobrou. | V10: Bom, já que a noite vai ser longa… vamos fazer direito. Cada um manda uma palavra no grupo, na ordem da roda. Quem sobrar, sobrou. | W10: Procedimento, para fazer direito: cada um manda uma palavra no grupo, na ordem da roda. Quem sobrar, sobrou. | X10: =SUMPRODUCT(($G10:$P10<>"")*ISERROR(SEARCH($G10:$P10,R10)))+SUMPRODUCT(($G10:$P10<>"")*ISERROR(SEARCH($G10:$P10,S10)))+SUMPRODUCT(($G10:$P10<>"")*ISERROR(SEARCH($G10:$P10,T10)))+SUMPRODUCT(($G10:$P10<>"")*ISERROR(SEARCH($G10:$P10,U10)))+SUMPRODUCT(($G10:$P10<>"")*ISERROR(SEARCH($G10:$P10,V10)))+SUMPRODUCT(($G10:$P10<>"")*ISERROR(SEARCH($G10:$P10,W10))) | Y10: Enquadre: "X pôs o celular na mesa:". Falante varia por partida (M.conduz), texto fixo.
A11: c2-10 | B11: a chamada no grupo | C11: chat | D11: cada personagem da roda (não o jogador) | E11: grupo | G11: Aqui | Q11: Aqui. | R11: Aqui! | S11: …aqui. | T11: Aqui? | U11: Aqui. | V11: Aqui… | W11: Aqui. | X11: =SUMPRODUCT(($G11:$P11<>"")*ISERROR(SEARCH($G11:$P11,R11)))+SUMPRODUCT(($G11:$P11<>"")*ISERROR(SEARCH($G11:$P11,S11)))+SUMPRODUCT(($G11:$P11<>"")*ISERROR(SEARCH($G11:$P11,T11)))+SUMPRODUCT(($G11:$P11<>"")*ISERROR(SEARCH($G11:$P11,U11)))+SUMPRODUCT(($G11:$P11<>"")*ISERROR(SEARCH($G11:$P11,V11)))+SUMPRODUCT(($G11:$P11<>"")*ISERROR(SEARCH($G11:$P11,W11))) | Y11: Resposta de chamada: precisa continuar curtíssima (a cena conta "uma palavra" por pessoa). O código distribui as palavras em rodízio pela lista pal.
A12: c2-11 | B12: a chamada no grupo | C12: chat | D12: cada personagem da roda (não o jogador) | E12: grupo | G12: Presente | Q12: Presente. | R12: Presente! | S12: …presente. | T12: Presente? | U12: Presente. | V12: Presente… | W12: Presente. | X12: =SUMPRODUCT(($G12:$P12<>"")*ISERROR(SEARCH($G12:$P12,R12)))+SUMPRODUCT(($G12:$P12<>"")*ISERROR(SEARCH($G12:$P12,S12)))+SUMPRODUCT(($G12:$P12<>"")*ISERROR(SEARCH($G12:$P12,T12)))+SUMPRODUCT(($G12:$P12<>"")*ISERROR(SEARCH($G12:$P12,U12)))+SUMPRODUCT(($G12:$P12<>"")*ISERROR(SEARCH($G12:$P12,V12)))+SUMPRODUCT(($G12:$P12<>"")*ISERROR(SEARCH($G12:$P12,W12))) | Y12: Resposta de chamada: precisa continuar curtíssima (a cena conta "uma palavra" por pessoa). O código distribui as palavras em rodízio pela lista pal.
A13: c2-12 | B13: a chamada no grupo | C13: chat | D13: cada personagem da roda (não o jogador) | E13: grupo | G13: Eu | Q13: Eu. | R13: Eu! | S13: …eu. | T13: Eu? | U13: Eu. | V13: Eu… | W13: Eu. | X13: =SUMPRODUCT(($G13:$P13<>"")*ISERROR(SEARCH($G13:$P13,R13)))+SUMPRODUCT(($G13:$P13<>"")*ISERROR(SEARCH($G13:$P13,S13)))+SUMPRODUCT(($G13:$P13<>"")*ISERROR(SEARCH($G13:$P13,T13)))+SUMPRODUCT(($G13:$P13<>"")*ISERROR(SEARCH($G13:$P13,U13)))+SUMPRODUCT(($G13:$P13<>"")*ISERROR(SEARCH($G13:$P13,V13)))+SUMPRODUCT(($G13:$P13<>"")*ISERROR(SEARCH($G13:$P13,W13))) | Y13: Resposta de chamada: precisa continuar curtíssima (a cena conta "uma palavra" por pessoa). O código distribui as palavras em rodízio pela lista pal.
